Workbook

Sheet __FDSCACHE__
B1: This sheet contains FactSet XML data for use with this workbook's =FDS codes. Modifying the worksheet's contents may damage the workbook's =FDS functionality.

Sheet WACC
B1: ASML
A2: Total Liabilities | B2: 25614500000
A3: Long-Term Debt | B3: 4692200000
A4: % Debt | B4: 0.2251125
A5: Cost of Debt | B5: 0.0027066195
A6: Tax Rate | B6: 0.21
A7: Total Equity | B7: 16151600000
A8: % Equity | B8: 0.7748875
A9: CAPM | B9: 0.15898103
A10: Risk-Free Rate | B10: 0.04085
A11: Beta | B11: 1.7083302
A12: Market Risk Premium | B12: 0.06915
A13: Terminal Growth Rate | B13: 0.02
A14: WACC | B14: 0.12367376

Sheet DCF_Simple
D1: =Python!A31 -> 2017-06-30 | E1: =Python!A27 -> 2018-06-30 | F1: =Python!A23 -> 2019-06-30 | G1: =Python!A19 -> 2020-06-30 | H1: =Python!A15 -> 2021-06-30 | I1: =Python!A11 -> 2022-06-30 | J1: =Python!A7 -> 2023-06-30 | K1: =Python!A3 -> 2024-06-30 | L1: =EDATE(K1, 12) -> 45838 | M1: =EDATE(L1, 12) -> 46203 | N1: =EDATE(M1, 12) -> 46568 | O1: =EDATE(N1, 12) -> 46934 | P1: =EDATE(O1, 12) -> 47299 | Q1: =EDATE(P1, 12) -> 47664 | R1: =EDATE(Q1, 12) -> 48029 | S1: =EDATE(R1, 12) -> 48395 | ... U1: =EDATE(T1, 12) -> 49125
B3: Figures in millions | D3: =YEAR(D1) -> 2017 | E3: =YEAR(E1) -> 2018 | F3: =YEAR(F1) -> 2019 | G3: =YEAR(G1) -> 2020 | H3: =YEAR(H1) -> 2021 | I3: =YEAR(I1) -> 2022 | J3: =YEAR(J1) -> 2023 | K3: =YEAR(K1) -> 2024 | ... U3: =YEAR(U1) -> 2034 | V3: Terminal
B4: Revenue | D4: =IFERROR(INDEX(Python!$1:$1048576,MATCH(DCF_Simple!D$1,Python!$A:$A,0),MATCH(DCF_Simple!$B4,Python!$1:$1,0))/1000000,0) -> 7767 | E4: =IFERROR(INDEX(Python!$1:$1048576,MATCH(DCF_Simple!E$1,Python!$A:$A,0),MATCH(DCF_Simple!$B4,Python!$1:$1,0))/1000000,0) -> 10033.2 | F4: =IFERROR(INDEX(Python!$1:$1048576,MATCH(DCF_Simple!F$1,Python!$A:$A,0),MATCH(DCF_Simple!$B4,Python!$1:$1,0))/1000000,0) -> 10715.6 | G4: =IFERROR(INDEX(Python!$1:$1048576,MATCH(DCF_Simple!G$1,Python!$A:$A,0),MATCH(DCF_Simple!$B4,Python!$1:$1,0))/1000000,0) -> 12789.2 | H4: =IFERROR(INDEX(Python!$1:$1048576,MATCH(DCF_Simple!H$1,Python!$A:$A,0),MATCH(DCF_Simple!$B4,Python!$1:$1,0))/1000000,0) -> 16596.2 | I4: =IFERROR(INDEX(Python!$1:$1048576,MATCH(DCF_Simple!I$1,Python!$A:$A,0),MATCH(DCF_Simple!$B4,Python!$1:$1,0))/1000000,0) -> 19191.8 | J4: =IFERROR(INDEX(Python!$1:$1048576,MATCH(DCF_Simple!J$1,Python!$A:$A,0),MATCH(DCF_Simple!$B4,Python!$1:$1,0))/1000000,0) -> 25857 | K4: =IFERROR(INDEX(Python!$1:$1048576,MATCH(DCF_Simple!K$1,Python!$A:$A,0),MATCH(DCF_Simple!$B4,Python!$1:$1,0))/1000000,0) -> 25442.8 | L4: =K4*(1+L5) -> 35083.932 | M4: =L4*(1+M5) -> 41731.173 | N4: =M4*(1+N5) -> 49637.846 | O4: =N4*(1+O5) -> 59042.57 | P4: =O4*(1+P5) -> 70229.178 | Q4: =P4*(1+Q5) -> 83535.276 | R4: =Q4*(1+R5) -> 99362.439 | S4: =R4*(1+S5) -> 118188.32 | ... U4: =T4*(1+U5) -> 167216.54 | V4: =U4 -> 167216.54
B5: Growth (y/y) | E5: =IFERROR(E4/D4-1,"") -> 0.29177289 | F5: =IFERROR(F4/E4-1,"") -> 0.068014193 | G5: =IFERROR(G4/F4-1,"") -> 0.19351226 | H5: =IFERROR(H4/G4-1,"") -> 0.29767304 | I5: =IFERROR(I4/H4-1,"") -> 0.15639725 | J5: =IFERROR(J4/I4-1,"") -> 0.34729416 | K5: =IFERROR(K4/J4-1,"") -> -0.016018873 | L5: =Python!F2*0.65 -> 0.37893363 | M5: =L5/2 -> 0.18946681 | N5: =M5 -> 0.18946681 | O5: =N5 -> 0.18946681 | P5: =O5 -> 0.18946681 | Q5: =P5 -> 0.18946681 | R5: =Q5 -> 0.18946681 | S5: =R5 -> 0.18946681 | T5: =S5 -> 0.18946681 | U5: =T5 -> 0.18946681
B7: Free Cash Flow (FCF) | D7: =IFERROR(INDEX(Python!$1:$1048576,MATCH(DCF_Simple!D$1,Python!$A:$A,0),MATCH(DCF_Simple!$B7,Python!$1:$1,0))/1000000,0) -> 1495.3 | E7: =IFERROR(INDEX(Python!$1:$1048576,MATCH(DCF_Simple!E$1,Python!$A:$A,0),MATCH(DCF_Simple!$B7,Python!$1:$1,0))/1000000,0) -> 1897.2 | F7: =IFERROR(INDEX(Python!$1:$1048576,MATCH(DCF_Simple!F$1,Python!$A:$A,0),MATCH(DCF_Simple!$B7,Python!$1:$1,0))/1000000,0) -> 1157.3 | G7: =IFERROR(INDEX(Python!$1:$1048576,MATCH(DCF_Simple!G$1,Python!$A:$A,0),MATCH(DCF_Simple!$B7,Python!$1:$1,0))/1000000,0) -> 2475.9 | H7: =IFERROR(INDEX(Python!$1:$1048576,MATCH(DCF_Simple!H$1,Python!$A:$A,0),MATCH(DCF_Simple!$B7,Python!$1:$1,0))/1000000,0) -> 6552.8 | I7: =IFERROR(INDEX(Python!$1:$1048576,MATCH(DCF_Simple!I$1,Python!$A:$A,0),MATCH(DCF_Simple!$B7,Python!$1:$1,0))/1000000,0) -> 9237.6 | J7: =IFERROR(INDEX(Python!$1:$1048576,MATCH(DCF_Simple!J$1,Python!$A:$A,0),MATCH(DCF_Simple!$B7,Python!$1:$1,0))/1000000,0) -> 5758.3 | K7: =IFERROR(INDEX(Python!$1:$1048576,MATCH(DCF_Simple!K$1,Python!$A:$A,0),MATCH(DCF_Simple!$B7,Python!$1:$1,0))/1000000,0) -> 2930.7 | L7: =L8*L4 -> 8320.4175 | M7: =M8*M4 -> 9896.8605 | N7: =N8*N4 -> 11771.987 | O7: =O8*O4 -> 14002.388 | P7: =P8*P4 -> 16655.376 | Q7: =Q8*Q4 -> 19811.017 | R7: =R8*R4 -> 23564.547 | S7: =S8*S4 -> 28029.247 | ... U7: =U8*U4 -> 39656.655 | V7: =U7 -> 39656.655
B8: FCF Margin | D8: =IFERROR(D7/D$4,"") -> 0.19251963 | E8: =IFERROR(E7/E$4,"") -> 0.18909221 | F8: =IFERROR(F7/F$4,"") -> 0.10800142 | G8: =IFERROR(G7/G$4,"") -> 0.19359303 | H8: =IFERROR(H7/H$4,"") -> 0.39483737 | I8: =IFERROR(I7/I$4,"") -> 0.48133057 | J8: =IFERROR(J7/J$4,"") -> 0.22269792 | K8: =IFERROR(K7/K$4,"") -> 0.11518779 | L8: =AVERAGE(D8:K8) -> 0.23715749 | M8: =L8 -> 0.23715749 | N8: =M8 -> 0.23715749 | O8: =N8 -> 0.23715749 | P8: =O8 -> 0.23715749 | Q8: =P8 -> 0.23715749 | R8: =Q8 -> 0.23715749 | S8: =R8 -> 0.23715749 | T8: =S8 -> 0.23715749 | U8: =T8 -> 0.23715749
B10: Shares Outstanding, Diluted | D10: =IFERROR(INDEX(Python!$1:$1048576,MATCH(DCF_Simple!D$1,Python!$A:$A,0),MATCH(DCF_Simple!$B10,Python!$1:$1,0))/1000000,0) -> 434.83304 | E10: =IFERROR(INDEX(Python!$1:$1048576,MATCH(DCF_Simple!E$1,Python!$A:$A,0),MATCH(DCF_Simple!$B10,Python!$1:$1,0))/1000000,0) -> 427.6 | F10: =IFERROR(INDEX(Python!$1:$1048576,MATCH(DCF_Simple!F$1,Python!$A:$A,0),MATCH(DCF_Simple!$B10,Python!$1:$1,0))/1000000,0) -> 421.8 | G10: =IFERROR(INDEX(Python!$1:$1048576,MATCH(DCF_Simple!G$1,Python!$A:$A,0),MATCH(DCF_Simple!$B10,Python!$1:$1,0))/1000000,0) -> 419.55307 | H10: =IFERROR(INDEX(Python!$1:$1048576,MATCH(DCF_Simple!H$1,Python!$A:$A,0),MATCH(DCF_Simple!$B10,Python!$1:$1,0))/1000000,0) -> 412 | I10: =IFERROR(INDEX(Python!$1:$1048576,MATCH(DCF_Simple!I$1,Python!$A:$A,0),MATCH(DCF_Simple!$B10,Python!$1:$1,0))/1000000,0) -> 401.6 | J10: =IFERROR(INDEX(Python!$1:$1048576,MATCH(DCF_Simple!J$1,Python!$A:$A,0),MATCH(DCF_Simple!$B10,Python!$1:$1,0))/1000000,0) -> 394 | K10: =IFERROR(INDEX(Python!$1:$1048576,MATCH(DCF_Simple!K$1,Python!$A:$A,0),MATCH(DCF_Simple!$B10,Python!$1:$1,0))/1000000,0) -> 393.5 | L10: =K10*(1+L11) -> 387.93682 | M10: =L10*(1+M11) -> 382.45229 | N10: =M10*(1+N11) -> 377.04529 | O10: =N10*(1+O11) -> 371.71474 | P10: =O10*(1+P11) -> 366.45955 | Q10: =P10*(1+Q11) -> 361.27866 | R10: =Q10*(1+R11) -> 356.17101 | S10: =R10*(1+S11) -> 351.13557 | ... U10: =T10*(1+U11) -> 341.27726 | V10: =U10 -> 341.27726
B11: Change (y/y) | E11: =IFERROR(E10/D10-1,"") -> -0.016634065 | F11: =IFERROR(F10/E10-1,"") -> -0.013564079 | G11: =IFERROR(G10/F10-1,"") -> -0.0053269986 | H11: =IFERROR(H10/G10-1,"") -> -0.018002662 | I11: =IFERROR(I10/H10-1,"") -> -0.025242718 | J11: =IFERROR(J10/I10-1,"") -> -0.018924303 | K11: =IFERROR(K10/J10-1,"") -> -0.0012690355 | L11: =AVERAGE(E11:K11) -> -0.014137694 | M11: =L11 -> -0.014137694 | N11: =M11 -> -0.014137694 | O11: =N11 -> -0.014137694 | P11: =O11 -> -0.014137694 | Q11: =P11 -> -0.014137694 | R11: =Q11 -> -0.014137694 | S11: =R11 -> -0.014137694 | T11: =S11 -> -0.014137694 | U11: =T11 -> -0.014137694
B13: FCF per share | D13: =IFERROR(D7/D10,0) -> 3.4387911 | E13: =IFERROR(E7/E10,0) -> 4.4368569 | F13: =IFERROR(F7/F10,0) -> 2.7437174 | G13: =IFERROR(G7/G10,0) -> 5.9012796 | H13: =IFERROR(H7/H10,0) -> 15.904854 | I13: =IFERROR(I7/I10,0) -> 23.001992 | J13: =IFERROR(J7/J10,0) -> 14.614975 | K13: =IFERROR(K7/K10,0) -> 7.4477764 | L13: =L7/L10 -> 21.447868 | M13: =M7/M10 -> 25.877373 | N13: =N7/N10 -> 31.221679 | O13: =O7/O10 -> 37.669714 | P13: =P7/P10 -> 45.449425 | Q13: =Q7/Q10 -> 54.835835 | R13: =R7/R10 -> 66.160766 | S13: =S7/S10 -> 79.824571 | ... U13: =U7/U10 -> 116.2007 | V13: =U13*(1+WACC!$B$13)/(WACC!$B$14-WACC!$B$13) -> 1143.247
B14: Discounted FCF per share | L14: =L13/((1+WACC!$B$14)^(L3-$K$3)) -> 19.087273 | M14: =M13/((1+WACC!$B$14)^(M3-$K$3)) -> 20.494613 | N14: =N13/((1+WACC!$B$14)^(N3-$K$3)) -> 22.005718 | O14: =O13/((1+WACC!$B$14)^(O3-$K$3)) -> 23.62824 | P14: =P13/((1+WACC!$B$14)^(P3-$K$3)) -> 25.370393 | Q14: =Q13/((1+WACC!$B$14)^(Q3-$K$3)) -> 27.240999 | R14: =R13/((1+WACC!$B$14)^(R3-$K$3)) -> 29.249528 | S14: =S13/((1+WACC!$B$14)^(S3-$K$3)) -> 31.406149 | ... U14: =U13/((1+WACC!$B$14)^(U3-$K$3)) -> 36.208151 | V14: =V13/((1+WACC!$B$14)^(U3-$K$3)) -> 356.2359
B17: Terminal Value (TV) | C17: =V14 -> 356.2359 | L17: =C17/$C$19 -> 0.57029795 | U17: =U14*20 -> 724.16302
B18: Total Discounted FCF | C18: =SUM(14:14)-V14 -> 268.41285 | L18: =C18/$C$19 -> 0.42970205 | U18: =U13*20 -> 2324.0139
B19: Enterprise Value | C19: =C17+C18 -> 624.64875
B20: Cash and Equivalents | C20: =Python!C3/1000000/K10 -> 7.4477764
B21: Debt | C21: =WACC!B3/1000000/K10 -> 11.924269
B22: Equity Value | C22: =C19+C20-C21 -> 620.17226

Sheet Python
A1: fiscalDateEnding | B1: Revenue | C1: Free Cash Flow (FCF) | D1: Shares Outstanding, Diluted | E1: Cash and Equivalents | F1: estimatedRevGrowth_yearly
A2: 2024-09-29 | B2: 26237100000 | C2: 2839400000 | D2: 393600000 | E2: 4984500000 | F2: 0.58297481
A3: 2024-06-30 | B3: 25442800000 | C3: 2930700000 | D3: 393500000 | E3: 5018900000 | F3: -0.048104255
A4: 2024-03-31 | B4: 26102300000 | C4: 2392200000 | D4: 393700000 | E4: 5406100000
A5: 2023-12-31 | B5: 27558500000 | C5: 3269500000 | D5: 393800000 | E5: 7010100000
A6: 2023-09-30 | B6: 26751700000 | C6: 5571700000 | D6: 393700000 | E6: 4980900000
A7: 2023-06-30 | B7: 25857000000 | C7: 5758300000 | D7: 394000000 | E7: 6346400000
A8: 2023-03-31 | B8: 24385200000 | C8: 8226800000 | D8: 394800000 | E8: 6652500000
A9: 2022-12-31 | B9: 21173400000 | C9: 7199000000 | D9: 395200000 | E9: 7376000000 | F9: 0.30445684
A10: 2022-10-02 | B10: 19728800000 | C10: 8445900000 | D10: 396600000 | E10: 3362800000
A11: 2022-06-30 | B11: 19191800000 | C11: 9237600000 | D11: 401600000 | E11: 4401900000 | F11: 0.39058007
A12: 2022-03-31 | B12: 17781500000 | C12: 10250000000 | D12: 401500000 | E12: 4722600000 | F12: -0.31988605
A13: 2021-12-31 | B13: 18611000000 | C13: 9945100000 | D13: 405000000 | E13: 7590300000 | F13: 0.39689241
A14: 2021-09-30 | B14: 17879500000 | C14: 8178800000 | D14: 408600000 | E14: 4455700000 | F14: 0.60378979
A15: 2021-06-30 | B15: 16596200000 | C15: 6552800000 | D15: 412000000 | E15: 5373300000 | F15: 0.90871095
A16: 2021-03-31 | B16: 15901700000 | C16: 3371800000 | D16: 416062500 | E16: 4655400000 | F16: 0.2907072
A17: 2020-12-31 | B17: 13978400000 | C17: 3665600000 | D17: 418400000 | E17: 7351600000 | F17: -0.0082418841
A18: 2020-09-30 | B18: 13760700000 | C18: 2570900000 | D18: 419565217 | E18: 4407800000
A19: 2020-06-30 | B19: 12789200000 | C19: 2475900000 | D19: 419553072 | E19: 4440300000 | F19: 0.28188959
A20: 2020-03-31 | B20: 12031400000 | C20: 2300300000 | D20: 420000000 | E20: 4111800000 | F20: 0.35440877
A21: 2019-12-31 | B21: 11819900000 | C21: 2509800000 | D21: 421355724 | E21: 4718100000 | F21: 0.13532357
A22: 2019-09-30 | B22: 10926000000 | C22: 683300000 | D22: 421700000 | E22: 2069900000 | F22: 0.049227066
A23: 2019-06-30 | B23: 10715600000 | C23: 1157300000 | D23: 421800000 | E23: 2334600000 | F23: -0.17904208
A24: 2019-03-31 | B24: 10888100000 | C24: 1815000000 | D24: 423095238 | E24: 3275100000 | F24: 0.24164388
A25: 2018-12-31 | B25: 10944000000 | C25: 2498700001 | D25: 423600000 | E25: 4034400000 | F25: 0.18081279
A26: 2018-09-30 | B26: 10361900000 | C26: 1950500001 | D26: 425900000 | E26: 2947500000 | F26: 0.10297138
A27: 2018-06-30 | B27: 10033200000 | C27: 1897200001 | D27: 427600000 | E27: 2980000000 | F27: 0.11122565
A28: 2018-03-31 | B28: 9394200000 | C28: 1660800001 | D28: 428900000 | E28: 3194100000 | F28: 0.10802734
A29: 2017-12-31 | B29: 9052800000 | C29: 1479400000 | D29: 430300000 | E29: 3288300000 | F29: 0.30104774
A30: 2017-09-30 | B30: 8399800000 | C30: 1767300000 | D30: 432000000 | E30: 2677600000 | F30: 0.10825629
... A84: 2004-03-31 | B84: 1674791363 | C84: 5.1248402e+08 | D84: 373744910 | E84: 1150579184 | F84: 0.97722348
A85: 2003-12-31 | B85: 1539044351 | C85: 4.371286e+08 | D85: 373744910 | E85: 1026012216
A86: 2003-09-30 | B86: 1588359865 | C86: 1.8727895e+08 | D86: 371313250 | E86: 1102990931 | F86: -0.17808885
A87: 2003-06-30 | B87: 1803453114 | C87: 235638316 | D87: 371281680 | E87: 1247512672 | F87: -0.21097696
A88: 2003-03-31 | B88: 1872363801 | C88: 21383900 | D88: 371280140 | E88: 686408212 | F88: 1.6886241
A89: 2002-12-31 | B89: 2006419040 | C89: 0 | D89: 371280140 | E89: 668318813 | F89: 15.692118
A90: 2002-09-30 | B90: 1912301524 | C90: 0 | D90: 367338889
A91: 2002-06-30 | B91: 1742881707 | C91: 0 | D91: 369024040 | E91: 582050344 | F91: -0.29289808
A92: 2002-03-31 | B92: 1856401621 | C92: 0 | D92: 362369700
A93: 2001-12-31 | B93: 1900875244 | C93: 0 | D93: 362369700 | E93: 912263136
...

Sheet Sheet3
A1: date | B1: revenue | C1: Deriv1 | D1: Static1 | F1: revenue | G1: Deriv1 | H1: Static1 | J1: grossProfit_margin | K1: Deriv1 | L1: Static1 | N1: FCF_margin | O1: Deriv1 | P1: Static1 | R1: 2025 | S1: =R1+1 -> 2026 | T1: =S1+1 -> 2027 | U1: =T1+1 -> 2028 | V1: =U1+1 -> 2029 | W1: =V1+1 -> 2030 | X1: =W1+1 -> 2031 | Y1: =X1+1 -> 2032 | Z1: =Y1+1 -> 2033 | ... AT1: =AS1+1 -> 2053
A2: 45596 | B2: 0.24979962 | C2: =B2/B3-1 -> -0.21198857 | D2: =B2-B3 -> -0.067200378 | F2: 0.24979962 | G2: =F2/F6-1 -> -0.29235235 | H2: =F2-F6 -> -0.10320038 | R2: =F2 -> 0.24979962 | S2: =R2*(1+$G$32) -> 0.2064695 | T2: =S2*(1+$G$32) -> 0.17065541 | U2: =T2*(1+$G$32) -> 0.14105361 | V2: =U2*(1+$G$32) -> 0.11658652 | W2: =V2*(1+$G$32) -> 0.096363479 | X2: =W2*(1+$G$32) -> 0.079648318 | Y2: =X2*(1+$G$32) -> 0.06583256 | Z2: =Y2*(1+$G$32) -> 0.054413277 | ... AT2: =AS2*(1+$G$32) -> 0.0012050017
A3: 2024-07-31 | B3: 0.317 | C3: =B3/B4-1 -> -0.039393939 | D3: =B3-B4 -> -0.013 | F3: 0.317 | G3: =F3/F7-1 -> -0.13623978 | H3: =F3-F7 -> -0.05 | J3: 0.753 | K3: =J3/J7-1 -> 0.017567568 | L3: =J3-J7 -> 0.013 | N3: 0.315 | O3: =N3/N7-1 -> 0.043046358 | P3: =N3-N7 -> 0.013 | R3: =J3 -> 0.753 | S3: =R3*(1+($K$32/2)) -> 0.75961419 | T3: =S3*(1+($K$32/2)) -> 0.76628648 | U3: =T3*(1+($K$32/2)) -> 0.77301737 | V3: =U3*(1+($K$32/2)) -> 0.77980739 | W3: =V3*(1+($K$32/2)) -> 0.78665705 | X3: =W3*(1+($K$32/2)) -> 0.79356687 | Y3: =X3*(1+($K$32/2)) -> 0.80053739 | Z3: =Y3*(1+($K$32/2)) -> 0.80756914 | ... AT3: =AS3*(1+($K$32/2)) -> 0.96192577
A4: 2024-04-30 | B4: 0.33 | C4: =B4/B5-1 -> 0.012269939 | D4: =B4-B5 -> 0.004 | F4: 0.33 | G4: =F4/F8-1 -> -0.21428571 | H4: =F4-F8 -> -0.09 | J4: 0.753 | K4: =J4/J8-1 -> 0.021709634 | L4: =J4-J8 -> 0.016 | N4: 0.312 | O4: =N4/N8-1 -> 0.02295082 | P4: =N4-N8 -> 0.007
A5: 2024-01-31 | B5: 0.326 | C5: =B5/B6-1 -> -0.076487252 | D5: =B5-B6 -> -0.027 | F5: 0.326 | G5: =F5/F9-1 -> -0.31941545 | H5: =F5-F9 -> -0.153 | J5: 0.752 | K5: =J5/J9-1 -> 0.027322404 | L5: =J5-J9 -> 0.02 | N5: 0.304 | O5: =N5/N9-1 -> 0.0099667774 | P5: =N5-N9 -> 0.003
A6: 2023-10-31 | B6: 0.353 | C6: =B6/B7-1 -> -0.038147139 | D6: =B6-B7 -> -0.014 | F6: 0.353 | G6: =F6/F10-1 -> -0.33143939 | H6: =F6-F10 -> -0.175 | J6: 0.746 | K6: =J6/J10-1 -> 0.014965986 | L6: =J6-J10 -> 0.011 | N6: 0.303 | O6: =N6/N10-1 -> 0.037671233 | P6: =N6-N10 -> 0.011 | R6: # Get a mathematical function written to get the first derivative. Maybe start with a graph, and go from there?
A7: 2023-07-31 | B7: 0.367 | C7: =B7/B8-1 -> -0.12619048 | D7: =B7-B8 -> -0.053 | F7: 0.367 | G7: =F7/F11-1 -> -0.37264957 | H7: =F7-F11 -> -0.218 | J7: 0.74 | K7: =J7/J11-1 -> 0.0040705563 | L7: =J7-J11 -> 0.003 | N7: 0.302 | O7: =N7/N11-1 -> 0.02027027 | P7: =N7-N11 -> 0.006 | S7: calculus functions in python/r, to start, do a static program maybe, just to get a foundation going. Might be a little bit of a detour for now
A8: 2023-04-30 | B8: 0.42 | C8: =B8/B9-1 -> -0.12317328 | D8: =B8-B9 -> -0.059 | F8: 0.42 | G8: =F8/F12-1 -> -0.31260229 | H8: =F8-F12 -> -0.191 | J8: 0.737 | K8: =J8/J12-1 -> 0.0013586957 | L8: =J8-J12 -> 0.001 | N8: 0.305 | O8: =N8/N12-1 -> 0.037414966 | P8: =N8-N12 -> 0.011
A9: 2023-01-31 | B9: 0.479 | C9: =B9/B10-1 -> -0.09280303 | D9: =B9-B10 -> -0.049 | F9: 0.479 | G9: =F9/F13-1 -> -0.23604466 | H9: =F9-F13 -> -0.148 | J9: 0.732 | K9: =J9/J13-1 -> -0.0054347826 | L9: =J9-J13 -> -0.004 | N9: 0.301 | O9: =N9/N13-1 -> -0.0098684211 | P9: =N9-N13 -> -0.003 | R9: I am leaving off by trying to determine a systematic way to project revenue growth. Keep it as simple as can be, for now
A10: 2022-10-31 | B10: 0.528 | C10: =B10/B11-1 -> -0.097435897 | D10: =B10-B11 -> -0.057 | F10: 0.528 | G10: =F10/F14-1 -> -0.16850394 | H10: =F10-F14 -> -0.107 | J10: 0.735 | K10: =J10/J14-1 -> -0.0040650407 | L10: =J10-J14 -> -0.003 | N10: 0.292 | O10: =N10/N14-1 -> -0.0875 | P10: =N10-N14 -> -0.028 | R10: Current figures are quarterly. I need annual
A11: 2022-07-31 | B11: 0.585 | C11: =B11/B12-1 -> -0.042553191 | D11: =B11-B12 -> -0.026 | F11: 0.585 | G11: =F11/F15-1 -> -0.16068867 | H11: =F11-F15 -> -0.112 | J11: 0.737 | K11: =J11/J15-1 -> -0.0027063599 | L11: =J11-J15 -> -0.002 | N11: 0.296 | O11: =N11/N15-1 -> -0.075 | P11: =N11-N15 -> -0.024
A12: 2022-04-30 | B12: 0.611 | C12: =B12/B13-1 -> -0.025518341 | D12: =B12-B13 -> -0.016 | F12: 0.611 | G12: =F12/F16-1 -> -0.12838802 | H12: =F12-F16 -> -0.09 | J12: 0.736 | K12: =J12/J16-1 -> -0.0040595399 | L12: =J12-J16 -> -0.003 | N12: 0.294 | O12: =N12/N16-1 -> -0.089783282 | P12: =N12-N16 -> -0.029
A13: 2022-01-31 | B13: 0.627 | C13: =B13/B14-1 -> -0.012598425 | D13: =B13-B14 -> -0.008 | F13: 0.627 | G13: =F13/F17-1 -> -0.15498652 | H13: =F13-F17 -> -0.115 | J13: 0.736 | K13: =J13/J17-1 -> -0.0013568521 | L13: =J13-J17 -> -0.001 | N13: 0.304 | O13: =N13/N17-1 -> -0.092537313 | P13: =N13-N17 -> -0.031
A14: 2021-10-31 | B14: 0.635 | C14: =B14/B15-1 -> -0.088952654 | D14: =B14-B15 -> -0.062 | F14: 0.635 | G14: =F14/F18-1 -> -0.25990676 | H14: =F14-F18 -> -0.223 | J14: 0.738 | K14: =J14/J18-1 -> 0.012345679 | L14: =J14-J18 -> 0.009 | N14: 0.32 | O14: =N14/N18-1 -> -0.0092879257 | P14: =N14-N18 -> -0.003 | R14: add more to show the return, and also the market cap valuations
A15: 2021-07-31 | B15: 0.697 | C15: =B15/B16-1 -> -0.0057061341 | D15: =B15-B16 -> -0.004 | F15: 0.697 | G15: =F15/F19-1 -> -0.1702381 | H15: =F15-F19 -> -0.143 | J15: 0.739 | K15: =J15/J19-1 -> 0.023545706 | L15: =J15-J19 -> 0.017 | N15: 0.32 | O15: =N15/N19-1 -> 0.18081181 | P15: =N15-N19 -> 0.049
A16: 2021-04-30 | B16: 0.701 | C16: =B16/B17-1 -> -0.055256065 | D16: =B16-B17 -> -0.041 | F16: 0.701 | G16: =F16/F20-1 -> -0.17819461 | H16: =F16-F20 -> -0.152 | J16: 0.739 | K16: =J16/J20-1 -> 0.030683403 | L16: =J16-J20 -> 0.022 | N16: 0.323 | O16: =N16/N20-1 -> 0.57560976 | P16: =N16-N20 -> 0.118
A17: 2021-01-31 | B17: 0.742 | C17: =B17/B18-1 -> -0.13519814 | D17: =B17-B18 -> -0.116 | F17: 0.742 | G17: =F17/F21-1 -> -0.16722783 | H17: =F17-F21 -> -0.149 | J17: 0.737 | K17: =J17/J21-1 -> 0.043909348 | L17: =J17-J21 -> 0.031 | N17: 0.335 | O17: =N17/N21-1 -> 11.884615 | P17: =N17-N21 -> 0.309
A18: 2020-10-31 | B18: 0.858 | C18: =B18/B19-1 -> 0.021428571 | D18: =B18-B19 -> 0.018 | F18: 0.858 | G18: =F18/F22-1 -> -0.030508475 | H18: =F18-F22 -> -0.027 | J18: 0.729 | K18: =J18/J22-1 -> 0.050432277 | L18: =J18-J22 -> 0.035 | N18: 0.323 | O18: =N18/N22-1 -> -4.4361702 | P18: =N18-N22 -> 0.417
A19: 2020-07-31 | B19: 0.84 | C19: =B19/B20-1 -> -0.015240328 | D19: =B19-B20 -> -0.013 | F19: 0.84 | G19: =F19/F23-1 -> -0.10733262 | H19: =F19-F23 -> -0.101 | J19: 0.722 | K19: =J19/J23-1 -> 0.052478134 | L19: =J19-J23 -> 0.036 | N19: 0.271 | O19: =N19/N23-1 -> -2.6227545 | P19: =N19-N23 -> 0.438
A20: 2020-04-30 | B20: 0.853 | C20: =B20/B21-1 -> -0.042648709 | D20: =B20-B21 -> -0.038 | F20: 0.853 | G20: =F20/F24-1 -> -0.17344961 | H20: =F20-F24 -> -0.179 | J20: 0.717 | K20: =J20/J24-1 -> 0.062222222 | L20: =J20-J24 -> 0.042 | N20: 0.205 | O20: =N20/N24-1 -> -1.940367 | P20: =N20-N24 -> 0.423
A21: 2020-01-31 | B21: 0.891 | C21: =B21/B22-1 -> 0.006779661 | D21: =B21-B22 -> 0.006 | F21: 0.891 | G21: =F21/F25-1 -> -0.17346939 | H21: =F21-F25 -> -0.187 | J21: 0.706 | K21: =J21/J25-1 -> 0.084485407 | L21: =J21-J25 -> 0.055 | N21: 0.026 | O21: =N21/N25-1 -> -1.0988593 | P21: =N21-N25 -> 0.289
A22: 2019-10-31 | B22: 0.885 | C22: =B22/B23-1 -> -0.059511158 | D22: =B22-B23 -> -0.056 | F22: 0.885 | J22: 0.694 | N22: -0.094
A23: 2019-07-31 | B23: 0.941 | C23: =B23/B24-1 -> -0.088178295 | D23: =B23-B24 -> -0.091 | F23: 0.941 | J23: 0.686 | N23: -0.167
A24: 2019-04-30 | B24: 1.032 | C24: =B24/B25-1 -> -0.042671614 | D24: =B24-B25 -> -0.046 | F24: 1.032 | J24: 0.675 | N24: -0.218
A25: 2019-01-31 | B25: 1.078 | F25: 1.078 | J25: 0.651 | N25: -0.263
A26: 2018-10-31 | J26: 0.618 | N26: -0.364
A27: 2018-07-31
A28: 2018-04-30
A29: 2018-01-31
A31: Mean | C31: =AVERAGE(C2:C24) -> -0.059964107 | G31: =AVERAGE(G2:G24) -> -0.20439619 | K31: =AVERAGE(K2:K24) -> 0.022603918 | O31: =AVERAGE(O2:O8) -> 0.028553404
A32: Median | C32: =MEDIAN(C2:C24) -> -0.042671614 | G32: =MEDIAN(G2:G24) -> -0.1734595 | K32: =MEDIAN(K2:K24) -> 0.017567568 | O32: =MEDIAN(O2:O8) -> 0.030182893

Sheet Beta
B1: Years | C1: Timing Standard | D1: Beta | E1: CAPM
A2: 0 | B2: 3 | C2: M | D2: 1.8905263 | E2: 0.17157989
A3: 1 | B3: 3 | C3: W | D3: 1.925972 | E3: 0.17403096
A4: 2 | B4: 3 | C4: D | D4: 1.852076 | E4: 0.16892106
A5: 3 | B5: 5 | C5: M | D5: 1.4749219 | E5: 0.14284085
A6: 4 | B6: 5 | C6: W | D6: 1.5645844 | E6: 0.14904101
A7: 5 | B7: 5 | C7: D | D7: 1.4451132 | E7: 0.14077958
A8: 6 | B8: Mean | D8: 1.692199 | E8: 0.15786556
A9: 7 | B9: Median | D9: 1.7083302 | E9: 0.15898103
