Workbook

Sheet Financial Statements
A1: date | B1: revenue | C1: grossProfit | D1: generalAndAdministrativeExpenses | E1: sellingAndMarketingExpenses | F1: sellingGeneralAndAdministrativeExpenses | G1: researchAndDevelopmentExpenses | H1: otherExpenses | I1: operatingIncome | J1: interestExpense | K1: interestIncome | L1: incomeTaxExpense | M1: netIncome | N1: weightedAverageShsOut | O1: weightedAverageShsOutDil | P1: freeCashFlow | Q1: accountsReceivables | R1: accountsPayables | S1: inventory_x | T1: depreciationAndAmortization | U1: stockBasedCompensation | V1: deferredIncomeTax | W1: changeInWorkingCapital | X1: otherWorkingCapital | Y1: netChangeInCash | Z1: netCashProvidedByOperatingActivities | AA1: capitalExpenditure | AB1: investmentsInPropertyPlantAndEquipment | AC1: acquisitionsNet | AD1: purchasesOfInvestments | AE1: netCashUsedForInvestingActivites | AF1: debtRepayment | AG1: commonStockIssued | AH1: commonStockRepurchased | AI1: dividendsPaid | AJ1: netCashUsedProvidedByFinancingActivities | AK1: effectOfForexChangesOnCash | AL1: cashAndCashEquivalents | AM1: shortTermInvestments | AN1: cashAndShortTermInvestments | AO1: netReceivables | AP1: inventory_y | AQ1: otherCurrentAssets | AR1: totalCurrentAssets | AS1: propertyPlantEquipmentNet | AT1: goodwill | AU1: intangibleAssets | AV1: longTermInvestments | AW1: totalNonCurrentAssets | AX1: totalAssets | AY1: accountPayables | AZ1: shortTermDebt | BA1: longTermDebt | BB1: totalLiabilities | BC1: totalEquity | BD1: EBITDA | BE1: FCFsimple
A2: 2024-07-31 | B2: 963872000 | C2: 725523000 | D2: 106434000 | E2: 355471000 | F2: 460457000 | G2: 250908000 | H2: -1031000 | I2: 14158000 | J2: 6549000 | K2: 51526000 | L2: 10914000 | M2: 47013000 | N2: 244091000 | O2: 251265000 | P2: 272871000 | Q2: 41811000 | R2: -348000 | S2: 0 | T2: 52584000 | U2: 200877000 | V2: -1674000 | W2: -50919000 | X2: -92382000 | Y2: 336099000 | Z2: 326641000 | AA2: -53770000 | AB2: -53770000 | AC2: 4995000 | AD2: -1044000 | AE2: -49890000 | AF2: 0 | AG2: 57740000 | AH2: 0 | AI2: 0 | AJ2: 57496000 | AK2: 877000 | AL2: 4038536000 | AM2: 0 | AN2: 4038536000 | AO2: 661045000 | AP2: 0 | AQ2: 230821000 | AR2: 4930402000 | AS2: 694371000 | AT2: 721996000 | AU2: 115686000 | AV2: 58246000 | AW2: 2272072000 | AX2: 7202474000 | AY2: 21067000 | AZ2: 17031000 | BA2: 743238000 | BB2: 4311884000 | BC2: 2890590000 | BD2: 66742000 | BE2: 12972000
A3: 2024-04-30 | B3: 921036000 | C3: 696033000 | D3: 103734000 | E3: 350114000 | F3: 453848000 | G3: 235249000 | H3: 7656000 | I3: 6936000 | J3: 6511000 | K3: 45850000 | L3: 7667000 | M3: 42820000 | N3: 242389000 | O3: 250164000 | P3: 323066000 | Q3: 150249000 | R3: 276000 | S3: 0 | T3: 48684000 | U3: 183125000 | V3: -255000 | W3: 31632000 | X3: -118893000 | Y3: 327368000 | Z3: 383228000 | AA3: -60162000 | AB3: -60162000 | AC3: -95876000 | AD3: -1658000 | AE3: -50598000 | AF3: 0 | AG3: 823000 | AH3: 0 | AI3: 0 | AJ3: -3018000 | AK3: -1917000 | AL3: 3702437000 | AM3: 0 | AN3: 3702437000 | AO3: 702856000 | AP3: 0 | AQ3: 191678000 | AR3: 4596971000 | AS3: 675979000 | AT3: 721973000 | AU3: 122024000 | AV3: 58419000 | AW3: 2245014000 | AX3: 6841985000 | AY3: 21299000 | AZ3: 16020000 | BA3: 742866000 | BB3: 4273203000 | BC3: 2568781999 | BD3: 55620000 | BE3: -4542000
A4: 2024-01-31 | B4: 845335000 | C4: 636079000 | D4: 102737000 | E4: 290357000 | F4: 390982000 | G4: 213998000 | H4: 3616000 | I4: 31099000 | J4: 6422000 | K4: 41685000 | L4: 13609000 | M4: 53699000 | N4: 240856000 | O4: 247936000 | P4: 272980000 | Q4: -283557000 | R4: -21259000 | S4: -62886000 | T4: 42369000 | U4: 176272000 | V4: -1032000 | W4: 7042000 | X4: 311858000 | Y4: 406197000 | Z4: 347016000 | AA4: -74036000 | AB4: -74036000 | AC4: -281000 | AD4: -5000000 | AE4: 20395000 | AF4: 0 | AG4: 33460000 | AH4: 76375000 | AI4: 0 | AJ4: 33460000 | AK4: 5369000 | AL4: 3375069000 | AM4: 99591000 | AN4: 3474660000 | AO4: 853105000 | AP4: 1 | AQ4: 183172000 | AR4: 4510937000 | AS4: 668383000 | AT4: 638041000 | AU4: 114518000 | AV4: 56244000 | AW4: 2135583000 | AX4: 6646520000 | AY4: 28180000 | AZ4: 14150000 | BA4: 742494000 | BB4: 4309431000 | BC4: 2337089000 | BD4: 73468000 | BE4: -568000
A5: 2023-10-31 | B5: 786014000 | C5: 591010000 | D5: 105589000 | E5: 286186000 | F5: 391775000 | G5: 196072000 | H5: -474000 | I5: 3163000 | J5: 547000 | K5: 40086000 | L5: 9603000 | M5: 26665000 | N5: 239297000 | O5: 243799000 | P5: 239598000 | Q5: -20860000 | R5: 5343000 | S5: 55327000 | T5: 38425000 | U5: 159614000 | V5: -2003000 | W5: -11734000 | X5: -51544000 | Y5: -195858000 | Z5: 273518000 | AA5: -33920000 | AB5: -33920000 | AC5: -238749000 | AD5: -196167000 | AE5: -468836000 | AF5: 0 | AG5: 2053000 | AH5: 0 | AI5: 0 | AJ5: 2053000 | AK5: -4494000 | AL5: 2968872000 | AM5: 197522000 | AN5: 3166394000 | AO5: 561872000 | AP5: 209216000 | AQ5: 141651000 | AR5: 4079133000 | AS5: 631978000 | AT5: 637678000 | AU5: 109423000 | AV5: 59541000 | AW5: 1751923000 | AX5: 5831056000 | AY5: 56968000 | AZ5: 14430000 | BA5: 780493000 | BB5: 3770209000 | BC5: 2060847000 | BD5: 41588000 | BE5: 7668000
A6: 2023-07-31 | B6: 731626000 | C6: 548709000 | D6: 153246000 | E6: 231474000 | F6: 384720000 | G6: 179362000 | H6: -1734000 | I6: -15373000 | J6: 6444000 | K6: 36638000 | L6: 4611000 | M6: 8472000 | N6: 237911000 | O6: 242144000 | P6: 188791000 | Q6: -78371000 | R6: 15614000 | S6: 7559000 | T6: 33877000 | U6: 164777000 | V6: -97000 | W6: -23823000 | X6: 31375000 | Y6: 339439000 | Z6: 244781000 | AA6: -55990000 | AB6: -55990000 | AC6: -97750000 | AD6: -2250000 | AE6: 41760000 | AF6: 0 | AG6: 46906000 | AH6: 0 | AI6: 0 | AJ6: 49737000 | AK6: 1273000 | AL6: 3167215000 | AM6: 0 | AN6: 3167215000 | AO6: 539463000 | AP6: 197111000 | AQ6: 146597000 | AR6: 4050386000 | AS6: 607766000 | AT6: 430697000 | AU6: 79139000 | AV6: 59541000 | AW6: 1470072000 | AX6: 5520458000 | AY6: 37073000 | AZ6: 16133000 | BA6: 774438000 | BB6: 3650358000 | BC6: 1870100000 | BD6: 18504000 | BE6: -37486000
A7: 2023-04-30 | B7: 692580000 | C7: 523350000 | D7: 82634000 | E7: 281107000 | F7: 363741000 | G7: 179065000 | H7: 230000 | I7: 11295000 | J7: 6387000 | K7: 30521000 | L7: 4409000 | M7: 491000 | N7: 236414000 | O7: 240598000 | P7: 227726000 | Q7: 165089000 | R7: -18596000 | S7: 0 | T7: 30583000 | U7: 130856000 | V7: -255000 | W7: 80041000 | X7: -66452000 | Y7: 374641000 | Z7: 300892000 | AA7: -73166000 | AB7: -73166000 | AC7: 10902000 | AD7: -10803000 | AE7: 66031000 | AF7: 0 | AG7: 2651000 | AH7: 0 | AI7: 0 | AJ7: 7908000 | AK7: -190000 | AL7: 2829677000 | AM7: 100000000 | AN7: 2929677000 | AO7: 461092000 | AP7: 186901000 | AQ7: 131100000 | AR7: 3708770000 | AS7: 574180000 | AT7: 430755000 | AU7: 83215000 | AV7: 57877000 | AW7: 1429088000 | AX7: 5137858000 | AY7: 16900000 | AZ7: 16215000 | BA7: 778151000 | BB7: 3503499000 | BC7: 1634359000 | BD7: 41878000 | BE7: -31288000
A8: 2023-01-31 | B8: 637367000 | C8: 461763000 | D8: 84979000 | E8: 246439000 | F8: 331418000 | G8: 191845000 | H8: -2782000 | I8: -61500000 | J8: 6352000 | K8: 27016000 | L8: 5314000 | M8: -48932000 | N8: 235027000 | O8: 235027000 | P8: 207904000 | Q8: -140869000 | R8: -40470000 | S8: 0 | T8: 27850000 | U8: 152347000 | V8: -980000 | W8: 87465000 | X8: 268804000 | Y8: -11134000 | Z8: 273293000 | AA8: -65389000 | AB8: -65389000 | AC8: 115000 | AD8: -253866000 | AE8: -319140000 | AF8: 0 | AG8: 27233000 | AH8: 59419000 | AI8: 0 | AJ8: 27233000 | AK8: 5579000 | AL8: 2455369000 | AM8: 250000000 | AN8: 2705369000 | AO8: 626181000 | AP8: 186855000 | AQ8: 121862000 | AR8: 3640267000 | AS8: 532271000 | AT8: 430645000 | AU8: 86889000 | AV8: 47270000 | AW8: 1386273000 | AX8: 5026540000 | AY8: 45372000 | AZ8: 13046000 | BA8: 770572000 | BB8: 3539106000 | BC8: 1487434000 | BD8: -33650000 | BE8: -99039000
A9: 2022-10-31 | B9: 580882000 | C9: 422654000 | D9: 84148000 | E9: 239672000 | F9: 323820000 | G9: 155256000 | H9: 750000 | I9: -56422000 | J9: 6334000 | K9: 16245000 | L9: 8870000 | M9: -54631000 | N9: 233785000 | O9: 233785000 | P9: 174077000 | Q9: -66512000 | R9: 24213000 | S9: 0 | T9: 23622000 | U9: 140113000 | V9: 682000 | W9: 86693000 | X9: 128992000 | Y9: 147664000 | Z9: 242851000 | AA9: -68774000 | AB9: -68774000 | AC9: -18464000 | AD9: -10181000 | AE9: -97419000 | AF9: -1591000 | AG9: 1477000 | AH9: 0 | AI9: 0 | AJ9: -114000 | AK9: -2744000 | AL9: 2466551000 | AM9: 0 | AN9: 2466551000 | AO9: 485313000 | AP9: 162260000 | AQ9: 89489000 | AR9: 3203613000 | AS9: 455651000 | AT9: 430285000 | AU9: 89500000 | AV9: 46395000 | AW9: 1265830000 | AX9: 4469443000 | AY9: 89289000 | AZ9: 10423000 | BA9: 758617000 | BB9: 3131811000 | BC9: 1337632000 | BD9: -32800000 | BE9: -101574000
A10: 2022-07-31 | B10: 535153000 | C10: 394586000 | D10: 80263000 | E10: 224766000 | F10: 305029000 | G10: 137864000 | H10: 3380000 | I10: -48307000 | J10: 6335000 | K10: 7727000 | L10: 4778000 | M10: -49285000 | N10: 232554000 | O10: 232554000 | P10: 135757000 | Q10: -49670000 | R10: 37225000 | S10: 0 | T10: 21909000 | U10: 131550000 | V10: -148000 | W10: 63882000 | X10: 93969000 | Y10: 167658000 | Z10: 209906000 | AA10: -74149000 | AB10: -74149000 | AC10: 2501000 | AD10: -5000000 | AE10: -79149000 | AF10: 0 | AG10: 36258000 | AH10: 0 | AI10: 0 | AJ10: 38759000 | AK10: -1858000 | AL10: 2318858000 | AM10: 0 | AN10: 2318858000 | AO10: 418799000 | AP10: 1 | AQ10: 90198000 | AR10: 2975980000 | AS10: 411475000 | AT10: 416066000 | AU10: 89840000 | AV10: 35585000 | AW10: 1178256000 | AX10: 4154236000 | AY10: 53817000 | AZ10: 10316000 | BA10: 761601000 | BB10: 2910889000 | BC10: 1243347000 | BD10: -26398000 | BE10: -100547000
A11: 2022-04-30 | B11: 487834000 | C11: 361002000 | D11: 67954000 | E11: 193532000 | F11: 261486000 | G11: 123399000 | H11: 3212000 | I11: -23883000 | J11: 5752000 | K11: 1507000 | L11: 3440000 | M11: -30409000 | N11: 225164285 | O11: 231179000 | P11: 156832000 | Q11: -1058000 | R11: -36431000 | S11: 0 | T11: 20429000 | U11: 102494000 | V11: 1752000 | W11: 82401000 | X11: 119890000 | Y11: 156103000 | Z11: 214957000 | AA11: -58125000 | AB11: -58125000 | AC11: 1462000 | AD11: -2825000 | AE11: -60950000 | AF11: 0 | AG11: 3106000 | AH11: 0 | AI11: 0 | AJ11: 3106000 | AK11: -2472000 | AL11: 2152736000 | AM11: 0 | AN11: 2152736000 | AO11: 369130000 | AP11: 135681000 | AQ11: 75511000 | AR11: 2733058000 | AS11: 345010000 | AT11: 416228000 | AU11: 93945000 | AV11: 28665000 | AW11: 1102777000 | AX11: 3835835000 | AY11: 11024000 | AZ11: 9967000 | BA11: 762086000 | BB11: 2718838000 | BC11: 1116997000 | BD11: -3454000 | BE11: -61579000
A12: 2022-01-31 | B12: 431010000 | C12: 318390000 | D12: 74312000 | E12: 162594000 | F12: 236906000 | G12: 105018000 | H12: 1679000 | I12: -23534000 | J12: 6302000 | K12: 0 | L12: 13582000 | M12: -41980000 | N12: 229662000 | O12: 229662000 | P12: 127330000 | Q12: -84710000 | R12: 40281000 | S12: -48172000 | T12: 20491000 | U12: 92637000 | V12: -14682000 | W12: 65818000 | X12: 158419000 | Y12: 89125000 | Z12: 159718000 | AA12: -32388000 | AB12: -32388000 | AC12: -60772000 | AD12: -500000 | AE12: -93660000 | AF12: 0 | AG12: 25928000 | AH12: 50277000 | AI12: 0 | AJ12: 26178000 | AK12: -3111000 | AL12: 1996633000 | AM12: 0 | AN12: 1996633000 | AO12: 368145000 | AP12: 126822000 | AQ12: 79352000 | AR12: 2570952000 | AS12: 292312000 | AT12: 416445000 | AU12: 97336000 | AV12: 23632000 | AW12: 1047429000 | AX12: 3618381000 | AY12: 47634000 | AZ12: 9820000 | BA12: 764896000 | BB12: 2580738000 | BC12: 1037643000 | BD12: -3043000 | BE12: -35431000
A13: 2021-10-31 | B13: 380051000 | C13: 278387000 | D13: 56061000 | E13: 164960000 | F13: 221021000 | G13: 97630000 | H13: 690000 | I13: -40264000 | J13: 6403000 | K13: 1019000 | L13: 4473000 | M13: -50455000 | N13: 228293000 | O13: 228293000 | P13: 122823000 | Q13: -16387000 | R13: -12416000 | S13: 0 | T13: 17859000 | U13: 86666000 | V13: -339000 | W13: 73146000 | X13: 89533000 | Y13: 120457000 | Z13: 159058000 | AA13: -36235000 | AB13: -36235000 | AC13: 4250000 | AD13: -8500000 | AE13: -44735000 | AF13: 0 | AG13: 3304000 | AH13: 0 | AI13: 0 | AJ13: 7554000 | AK13: -1420000 | AL13: 1907508000 | AM13: 0 | AN13: 1907508000 | AO13: 283272000 | AP13: 108636000 | AQ13: 60670000 | AR13: 2360086000 | AS13: 276117000 | AT13: 373889000 | AU13: 82870000 | AV13: 22665000 | AW13: 939531000 | AX13: 3299617000 | AY13: 7167000 | AZ13: 9706000 | BA13: 767040000 | BB13: 2340047000 | BC13: 959570000 | BD13: -22405000 | BE13: -58640000
... A27: 2018-01-31 | B27: 38717000 | C27: 19547000 | D27: 6121000 | E27: 34265000 | F27: 40386000 | G27: 15928000 | H27: 0 | I27: -36767000 | J27: 0 | K27: 190000 | L27: 483000 | M27: -41717000 | N27: 43055020 | O27: 43055000 | P27: -10170000 | Q27: -19521000 | R27: 0 | S27: 0 | T27: -671000 | U27: 1338000 | V27: 0 | W27: -23235000 | X27: -3714000 | Y27: -2937000 | Z27: -6725000 | AA27: -3445000 | AB27: -3445000 | AC27: 0 | AD27: 0 | AE27: 53000 | AF27: 0 | AG27: 0 | AH27: 0 | AI27: 0 | AJ27: 3532000 | AK27: 203000 | AL27: 63179000 | AM27: 2593000 | AN27: 65772000 | AO27: 59614000 | AP27: 1 | AQ27: 28224999 | AR27: 153611000 | AS27: 30854000 | AT27: 8421000 | AU27: 11636000 | AV27: 0 | AW27: 64092000 | AX27: 217703000 | AY27: 12261000 | AZ27: 0 | BA27: 15971000 | BB27: 236161000 | BC27: -18458000 | BD27: -37438000 | BE27: -40883000

Sheet Margins
A1: date | B1: revenue | C1: grossProfit | D1: generalAndAdministrativeExpenses | E1: sellingAndMarketingExpenses | F1: sellingGeneralAndAdministrativeExpenses | G1: researchAndDevelopmentExpenses | H1: otherExpenses | I1: operatingIncome | J1: interestExpense | K1: interestIncome | L1: incomeTaxExpense | M1: netIncome | N1: weightedAverageShsOut | O1: weightedAverageShsOutDil | P1: freeCashFlow | Q1: accountsReceivables | R1: accountsPayables | S1: inventory_x | T1: depreciationAndAmortization | U1: stockBasedCompensation | V1: deferredIncomeTax | W1: changeInWorkingCapital | X1: otherWorkingCapital | Y1: netChangeInCash | Z1: netCashProvidedByOperatingActivities | AA1: capitalExpenditure | AB1: investmentsInPropertyPlantAndEquipment | AC1: acquisitionsNet | AD1: purchasesOfInvestments | AE1: netCashUsedForInvestingActivites | AF1: debtRepayment | AG1: commonStockIssued | AH1: commonStockRepurchased | AI1: dividendsPaid | AJ1: netCashUsedProvidedByFinancingActivities | AK1: effectOfForexChangesOnCash | AL1: cashAndCashEquivalents | AM1: shortTermInvestments | AN1: cashAndShortTermInvestments | AO1: netReceivables | AP1: inventory_y | AQ1: otherCurrentAssets | AR1: totalCurrentAssets | AS1: propertyPlantEquipmentNet | AT1: goodwill | AU1: intangibleAssets | AV1: longTermInvestments | AW1: totalNonCurrentAssets | AX1: totalAssets | AY1: accountPayables | AZ1: shortTermDebt | BA1: longTermDebt | BB1: totalLiabilities | BC1: totalEquity | BD1: EBITDA | BE1: FCFsimple
A2: 2024-07-31 | B2: 1 | C2: 0.753 | D2: 0.11 | E2: 0.369 | F2: 0.478 | G2: 0.26 | H2: -0.001 | I2: 0.015 | J2: 0.007 | K2: 0.053 | L2: 0.011 | M2: 0.049 | N2: 0.253 | O2: 0.261 | P2: 0.283 | Q2: 0.043 | R2: 0 | S2: 0 | T2: 0.055 | U2: 0.208 | V2: -0.002 | W2: -0.053 | X2: -0.096 | Y2: 0.349 | Z2: 0.339 | AA2: -0.056 | AB2: -0.056 | AC2: 0.005 | AD2: -0.001 | AE2: -0.052 | AF2: 0 | AG2: 0.06 | AH2: 0 | AI2: 0 | AJ2: 0.06 | AK2: 0.001 | AL2: 4.19 | AM2: 0 | AN2: 4.19 | AO2: 0.686 | AP2: 0 | AQ2: 0.239 | AR2: 5.115 | AS2: 0.72 | AT2: 0.749 | AU2: 0.12 | AV2: 0.06 | AW2: 2.357 | AX2: 7.472 | AY2: 0.022 | AZ2: 0.018 | BA2: 0.771 | BB2: 4.474 | BC2: 2.999 | BD2: 0.069 | BE2: 0.013
A3: 2024-04-30 | B3: 1 | C3: 0.756 | D3: 0.113 | E3: 0.38 | F3: 0.493 | G3: 0.255 | H3: 0.008 | I3: 0.008 | J3: 0.007 | K3: 0.05 | L3: 0.008 | M3: 0.046 | N3: 0.263 | O3: 0.272 | P3: 0.351 | Q3: 0.163 | R3: 0 | S3: 0 | T3: 0.053 | U3: 0.199 | V3: 0 | W3: 0.034 | X3: -0.129 | Y3: 0.355 | Z3: 0.416 | AA3: -0.065 | AB3: -0.065 | AC3: -0.104 | AD3: -0.002 | AE3: -0.055 | AF3: 0 | AG3: 0.001 | AH3: 0 | AI3: 0 | AJ3: -0.003 | AK3: -0.002 | AL3: 4.02 | AM3: 0 | AN3: 4.02 | AO3: 0.763 | AP3: 0 | AQ3: 0.208 | AR3: 4.991 | AS3: 0.734 | AT3: 0.784 | AU3: 0.132 | AV3: 0.063 | AW3: 2.437 | AX3: 7.429 | AY3: 0.023 | AZ3: 0.017 | BA3: 0.807 | BB3: 4.64 | BC3: 2.789 | BD3: 0.06 | BE3: -0.005
A4: 2024-01-31 | B4: 1 | C4: 0.752 | D4: 0.122 | E4: 0.343 | F4: 0.463 | G4: 0.253 | H4: 0.004 | I4: 0.037 | J4: 0.008 | K4: 0.049 | L4: 0.016 | M4: 0.064 | N4: 0.285 | O4: 0.293 | P4: 0.323 | Q4: -0.335 | R4: -0.025 | S4: -0.074 | T4: 0.05 | U4: 0.209 | V4: -0.001 | W4: 0.008 | X4: 0.369 | Y4: 0.481 | Z4: 0.411 | AA4: -0.088 | AB4: -0.088 | AC4: 0 | AD4: -0.006 | AE4: 0.024 | AF4: 0 | AG4: 0.04 | AH4: 0.09 | AI4: 0 | AJ4: 0.04 | AK4: 0.006 | AL4: 3.993 | AM4: 0.118 | AN4: 4.11 | AO4: 1.009 | AP4: 0 | AQ4: 0.217 | AR4: 5.336 | AS4: 0.791 | AT4: 0.755 | AU4: 0.135 | AV4: 0.067 | AW4: 2.526 | AX4: 7.863 | AY4: 0.033 | AZ4: 0.017 | BA4: 0.878 | BB4: 5.098 | BC4: 2.765 | BD4: 0.087 | BE4: -0.001
A5: 2023-10-31 | B5: 1 | C5: 0.752 | D5: 0.134 | E5: 0.364 | F5: 0.498 | G5: 0.249 | H5: -0.001 | I5: 0.004 | J5: 0.001 | K5: 0.051 | L5: 0.012 | M5: 0.034 | N5: 0.304 | O5: 0.31 | P5: 0.305 | Q5: -0.027 | R5: 0.007 | S5: 0.07 | T5: 0.049 | U5: 0.203 | V5: -0.003 | W5: -0.015 | X5: -0.066 | Y5: -0.249 | Z5: 0.348 | AA5: -0.043 | AB5: -0.043 | AC5: -0.304 | AD5: -0.25 | AE5: -0.596 | AF5: 0 | AG5: 0.003 | AH5: 0 | AI5: 0 | AJ5: 0.003 | AK5: -0.006 | AL5: 3.777 | AM5: 0.251 | AN5: 4.028 | AO5: 0.715 | AP5: 0.266 | AQ5: 0.18 | AR5: 5.19 | AS5: 0.804 | AT5: 0.811 | AU5: 0.139 | AV5: 0.076 | AW5: 2.229 | AX5: 7.419 | AY5: 0.072 | AZ5: 0.018 | BA5: 0.993 | BB5: 4.797 | BC5: 2.622 | BD5: 0.053 | BE5: 0.01
A6: 2023-07-31 | B6: 1 | C6: 0.75 | D6: 0.209 | E6: 0.316 | F6: 0.526 | G6: 0.245 | H6: -0.002 | I6: -0.021 | J6: 0.009 | K6: 0.05 | L6: 0.006 | M6: 0.012 | N6: 0.325 | O6: 0.331 | P6: 0.258 | Q6: -0.107 | R6: 0.021 | S6: 0.01 | T6: 0.046 | U6: 0.225 | V6: 0 | W6: -0.033 | X6: 0.043 | Y6: 0.464 | Z6: 0.335 | AA6: -0.077 | AB6: -0.077 | AC6: -0.134 | AD6: -0.003 | AE6: 0.057 | AF6: 0 | AG6: 0.064 | AH6: 0 | AI6: 0 | AJ6: 0.068 | AK6: 0.002 | AL6: 4.329 | AM6: 0 | AN6: 4.329 | AO6: 0.737 | AP6: 0.269 | AQ6: 0.2 | AR6: 5.536 | AS6: 0.831 | AT6: 0.589 | AU6: 0.108 | AV6: 0.081 | AW6: 2.009 | AX6: 7.545 | AY6: 0.051 | AZ6: 0.022 | BA6: 1.059 | BB6: 4.989 | BC6: 2.556 | BD6: 0.025 | BE6: -0.051
A7: 2023-04-30 | B7: 1 | C7: 0.756 | D7: 0.119 | E7: 0.406 | F7: 0.525 | G7: 0.259 | H7: 0 | I7: 0.016 | J7: 0.009 | K7: 0.044 | L7: 0.006 | M7: 0.001 | N7: 0.341 | O7: 0.347 | P7: 0.329 | Q7: 0.238 | R7: -0.027 | S7: 0 | T7: 0.044 | U7: 0.189 | V7: 0 | W7: 0.116 | X7: -0.096 | Y7: 0.541 | Z7: 0.434 | AA7: -0.106 | AB7: -0.106 | AC7: 0.016 | AD7: -0.016 | AE7: 0.095 | AF7: 0 | AG7: 0.004 | AH7: 0 | AI7: 0 | AJ7: 0.011 | AK7: 0 | AL7: 4.086 | AM7: 0.144 | AN7: 4.23 | AO7: 0.666 | AP7: 0.27 | AQ7: 0.189 | AR7: 5.355 | AS7: 0.829 | AT7: 0.622 | AU7: 0.12 | AV7: 0.084 | AW7: 2.063 | AX7: 7.418 | AY7: 0.024 | AZ7: 0.023 | BA7: 1.124 | BB7: 5.059 | BC7: 2.36 | BD7: 0.06 | BE7: -0.045
A8: 2023-01-31 | B8: 1 | C8: 0.724 | D8: 0.133 | E8: 0.387 | F8: 0.52 | G8: 0.301 | H8: -0.004 | I8: -0.096 | J8: 0.01 | K8: 0.042 | L8: 0.008 | M8: -0.077 | N8: 0.369 | O8: 0.369 | P8: 0.326 | Q8: -0.221 | R8: -0.063 | S8: 0 | T8: 0.044 | U8: 0.239 | V8: -0.002 | W8: 0.137 | X8: 0.422 | Y8: -0.017 | Z8: 0.429 | AA8: -0.103 | AB8: -0.103 | AC8: 0 | AD8: -0.398 | AE8: -0.501 | AF8: 0 | AG8: 0.043 | AH8: 0.093 | AI8: 0 | AJ8: 0.043 | AK8: 0.009 | AL8: 3.852 | AM8: 0.392 | AN8: 4.245 | AO8: 0.982 | AP8: 0.293 | AQ8: 0.191 | AR8: 5.711 | AS8: 0.835 | AT8: 0.676 | AU8: 0.136 | AV8: 0.074 | AW8: 2.175 | AX8: 7.886 | AY8: 0.071 | AZ8: 0.02 | BA8: 1.209 | BB8: 5.553 | BC8: 2.334 | BD8: -0.053 | BE8: -0.155
A9: 2022-10-31 | B9: 1 | C9: 0.728 | D9: 0.145 | E9: 0.413 | F9: 0.557 | G9: 0.267 | H9: 0.001 | I9: -0.097 | J9: 0.011 | K9: 0.028 | L9: 0.015 | M9: -0.094 | N9: 0.402 | O9: 0.402 | P9: 0.3 | Q9: -0.115 | R9: 0.042 | S9: 0 | T9: 0.041 | U9: 0.241 | V9: 0.001 | W9: 0.149 | X9: 0.222 | Y9: 0.254 | Z9: 0.418 | AA9: -0.118 | AB9: -0.118 | AC9: -0.032 | AD9: -0.018 | AE9: -0.168 | AF9: -0.003 | AG9: 0.003 | AH9: 0 | AI9: 0 | AJ9: 0 | AK9: -0.005 | AL9: 4.246 | AM9: 0 | AN9: 4.246 | AO9: 0.835 | AP9: 0.279 | AQ9: 0.154 | AR9: 5.515 | AS9: 0.784 | AT9: 0.741 | AU9: 0.154 | AV9: 0.08 | AW9: 2.179 | AX9: 7.694 | AY9: 0.154 | AZ9: 0.018 | BA9: 1.306 | BB9: 5.391 | BC9: 2.303 | BD9: -0.056 | BE9: -0.175
A10: 2022-07-31 | B10: 1 | C10: 0.737 | D10: 0.15 | E10: 0.42 | F10: 0.57 | G10: 0.258 | H10: 0.006 | I10: -0.09 | J10: 0.012 | K10: 0.014 | L10: 0.009 | M10: -0.092 | N10: 0.435 | O10: 0.435 | P10: 0.254 | Q10: -0.093 | R10: 0.07 | S10: 0 | T10: 0.041 | U10: 0.246 | V10: 0 | W10: 0.119 | X10: 0.176 | Y10: 0.313 | Z10: 0.392 | AA10: -0.139 | AB10: -0.139 | AC10: 0.005 | AD10: -0.009 | AE10: -0.148 | AF10: 0 | AG10: 0.068 | AH10: 0 | AI10: 0 | AJ10: 0.072 | AK10: -0.003 | AL10: 4.333 | AM10: 0 | AN10: 4.333 | AO10: 0.783 | AP10: 0 | AQ10: 0.169 | AR10: 5.561 | AS10: 0.769 | AT10: 0.777 | AU10: 0.168 | AV10: 0.066 | AW10: 2.202 | AX10: 7.763 | AY10: 0.101 | AZ10: 0.019 | BA10: 1.423 | BB10: 5.439 | BC10: 2.323 | BD10: -0.049 | BE10: -0.188
A11: 2022-04-30 | B11: 1 | C11: 0.74 | D11: 0.139 | E11: 0.397 | F11: 0.536 | G11: 0.253 | H11: 0.007 | I11: -0.049 | J11: 0.012 | K11: 0.003 | L11: 0.007 | M11: -0.062 | N11: 0.462 | O11: 0.474 | P11: 0.321 | Q11: -0.002 | R11: -0.075 | S11: 0 | T11: 0.042 | U11: 0.21 | V11: 0.004 | W11: 0.169 | X11: 0.246 | Y11: 0.32 | Z11: 0.441 | AA11: -0.119 | AB11: -0.119 | AC11: 0.003 | AD11: -0.006 | AE11: -0.125 | AF11: 0 | AG11: 0.006 | AH11: 0 | AI11: 0 | AJ11: 0.006 | AK11: -0.005 | AL11: 4.413 | AM11: 0 | AN11: 4.413 | AO11: 0.757 | AP11: 0.278 | AQ11: 0.155 | AR11: 5.602 | AS11: 0.707 | AT11: 0.853 | AU11: 0.193 | AV11: 0.059 | AW11: 2.261 | AX11: 7.863 | AY11: 0.023 | AZ11: 0.02 | BA11: 1.562 | BB11: 5.573 | BC11: 2.29 | BD11: -0.007 | BE11: -0.126
A12: 2022-01-31 | B12: 1 | C12: 0.739 | D12: 0.172 | E12: 0.377 | F12: 0.55 | G12: 0.244 | H12: 0.004 | I12: -0.055 | J12: 0.015 | K12: 0 | L12: 0.032 | M12: -0.097 | N12: 0.533 | O12: 0.533 | P12: 0.295 | Q12: -0.197 | R12: 0.093 | S12: -0.112 | T12: 0.048 | U12: 0.215 | V12: -0.034 | W12: 0.153 | X12: 0.368 | Y12: 0.207 | Z12: 0.371 | AA12: -0.075 | AB12: -0.075 | AC12: -0.141 | AD12: -0.001 | AE12: -0.217 | AF12: 0 | AG12: 0.06 | AH12: 0.117 | AI12: 0 | AJ12: 0.061 | AK12: -0.007 | AL12: 4.632 | AM12: 0 | AN12: 4.632 | AO12: 0.854 | AP12: 0.294 | AQ12: 0.184 | AR12: 5.965 | AS12: 0.678 | AT12: 0.966 | AU12: 0.226 | AV12: 0.055 | AW12: 2.43 | AX12: 8.395 | AY12: 0.111 | AZ12: 0.023 | BA12: 1.775 | BB12: 5.988 | BC12: 2.407 | BD12: -0.007 | BE12: -0.082
A13: 2021-10-31 | B13: 1 | C13: 0.732 | D13: 0.148 | E13: 0.434 | F13: 0.582 | G13: 0.257 | H13: 0.002 | I13: -0.106 | J13: 0.017 | K13: 0.003 | L13: 0.012 | M13: -0.133 | N13: 0.601 | O13: 0.601 | P13: 0.323 | Q13: -0.043 | R13: -0.033 | S13: 0 | T13: 0.047 | U13: 0.228 | V13: -0.001 | W13: 0.192 | X13: 0.236 | Y13: 0.317 | Z13: 0.419 | AA13: -0.095 | AB13: -0.095 | AC13: 0.011 | AD13: -0.022 | AE13: -0.118 | AF13: 0 | AG13: 0.009 | AH13: 0 | AI13: 0 | AJ13: 0.02 | AK13: -0.004 | AL13: 5.019 | AM13: 0 | AN13: 5.019 | AO13: 0.745 | AP13: 0.286 | AQ13: 0.16 | AR13: 6.21 | AS13: 0.727 | AT13: 0.984 | AU13: 0.218 | AV13: 0.06 | AW13: 2.472 | AX13: 8.682 | AY13: 0.019 | AZ13: 0.026 | BA13: 2.018 | BB13: 6.157 | BC13: 2.525 | BD13: -0.059 | BE13: -0.154
... A27: 2018-01-31 | B27: 1 | C27: 0.505 | D27: 0.158 | E27: 0.885 | F27: 1.043 | G27: 0.411 | H27: 0 | I27: -0.95 | J27: 0 | K27: 0.005 | L27: 0.012 | M27: -1.077 | N27: 1.112 | O27: 1.112 | P27: -0.263 | Q27: -0.504 | R27: 0 | S27: 0 | T27: -0.017 | U27: 0.035 | V27: 0 | W27: -0.6 | X27: -0.096 | Y27: -0.076 | Z27: -0.174 | AA27: -0.089 | AB27: -0.089 | AC27: 0 | AD27: 0 | AE27: 0.001 | AF27: 0 | AG27: 0 | AH27: 0 | AI27: 0 | AJ27: 0.091 | AK27: 0.005 | AL27: 1.632 | AM27: 0.067 | AN27: 1.699 | AO27: 1.54 | AP27: 0 | AQ27: 0.729 | AR27: 3.968 | AS27: 0.797 | AT27: 0.218 | AU27: 0.301 | AV27: 0 | AW27: 1.655 | AX27: 5.623 | AY27: 0.317 | AZ27: 0 | BA27: 0.413 | BB27: 6.1 | BC27: -0.477 | BD27: -0.967 | BE27: -1.056

Sheet Quarterly % Change
A1: date | B1: revenue | C1: grossProfit | D1: generalAndAdministrativeExpenses | E1: sellingAndMarketingExpenses | F1: sellingGeneralAndAdministrativeExpenses | G1: researchAndDevelopmentExpenses | H1: otherExpenses | I1: operatingIncome | J1: interestExpense | K1: interestIncome | L1: incomeTaxExpense | M1: netIncome | N1: weightedAverageShsOut | O1: weightedAverageShsOutDil | P1: freeCashFlow | Q1: accountsReceivables | R1: accountsPayables | S1: inventory_x | T1: depreciationAndAmortization | U1: stockBasedCompensation | V1: deferredIncomeTax | W1: changeInWorkingCapital | X1: otherWorkingCapital | Y1: netChangeInCash | Z1: netCashProvidedByOperatingActivities | AA1: capitalExpenditure | AB1: investmentsInPropertyPlantAndEquipment | AC1: acquisitionsNet | AD1: purchasesOfInvestments | AE1: netCashUsedForInvestingActivites | AF1: debtRepayment | AG1: commonStockIssued | AH1: commonStockRepurchased | AI1: dividendsPaid | AJ1: netCashUsedProvidedByFinancingActivities | AK1: effectOfForexChangesOnCash | AL1: cashAndCashEquivalents | AM1: shortTermInvestments | AN1: cashAndShortTermInvestments | AO1: netReceivables | AP1: inventory_y | AQ1: otherCurrentAssets | AR1: totalCurrentAssets | AS1: propertyPlantEquipmentNet | AT1: goodwill | AU1: intangibleAssets | AV1: longTermInvestments | AW1: totalNonCurrentAssets | AX1: totalAssets | AY1: accountPayables | AZ1: shortTermDebt | BA1: longTermDebt | BB1: totalLiabilities | BC1: totalEquity | BD1: EBITDA | BE1: FCFsimple
A2: 2024-07-31 | B2: 0.047 | C2: 0.042 | D2: 0.026 | E2: 0.015 | F2: 0.015 | G2: 0.067 | H2: -1.135 | I2: 1.041 | J2: 0.006 | K2: 0.124 | L2: 0.424 | M2: 0.098 | N2: 0.007 | O2: 0.004 | P2: -0.155 | Q2: -0.722 | R2: -2.261 | T2: 0.08 | U2: 0.097 | V2: 5.565 | W2: -2.61 | X2: -0.223 | Y2: 0.027 | Z2: -0.148 | AA2: -0.106 | AB2: -0.106 | AC2: -1.052 | AD2: -0.37 | AE2: -0.014 | AG2: 69.158 | AJ2: -20.051 | AK2: -1.457 | AL2: 0.091 | AN2: 0.091 | AO2: -0.059 | AQ2: 0.204 | AR2: 0.073 | AS2: 0.027 | AT2: 0 | AU2: -0.052 | AV2: -0.003 | AW2: 0.012 | AX2: 0.053 | AY2: -0.011 | AZ2: 0.063 | BA2: 0.001 | BB2: 0.009 | BC2: 0.125 | BD2: 0.2 | BE2: -3.856
A3: 2024-04-30 | B3: 0.09 | C3: 0.094 | D3: 0.01 | E3: 0.206 | F3: 0.161 | G3: 0.099 | H3: 1.117 | I3: -0.777 | J3: 0.014 | K3: 0.1 | L3: -0.437 | M3: -0.203 | N3: 0.006 | O3: 0.009 | P3: 0.183 | Q3: -1.53 | R3: -1.013 | S3: -1 | T3: 0.149 | U3: 0.039 | V3: -0.753 | W3: 3.492 | X3: -1.381 | Y3: -0.194 | Z3: 0.104 | AA3: -0.187 | AB3: -0.187 | AC3: 340.196 | AD3: -0.668 | AE3: -3.481 | AG3: -0.975 | AH3: -1 | AJ3: -1.09 | AK3: -1.357 | AL3: 0.097 | AM3: -1 | AN3: 0.066 | AO3: -0.176 | AP3: -1 | AQ3: 0.046 | AR3: 0.019 | AS3: 0.011 | AT3: 0.132 | AU3: 0.066 | AV3: 0.039 | AW3: 0.051 | AX3: 0.029 | AY3: -0.244 | AZ3: 0.132 | BA3: 0.001 | BB3: -0.008 | BC3: 0.099 | BD3: -0.243 | BE3: 6.996
A4: 2024-01-31 | B4: 0.075 | C4: 0.076 | D4: -0.027 | E4: 0.015 | F4: -0.002 | G4: 0.091 | H4: -8.629 | I4: 8.832 | J4: 10.74 | K4: 0.04 | L4: 0.417 | M4: 1.014 | N4: 0.007 | O4: 0.017 | P4: 0.139 | Q4: 12.593 | R4: -4.979 | S4: -2.137 | T4: 0.103 | U4: 0.104 | V4: -0.485 | W4: -1.6 | X4: -7.05 | Y4: -3.074 | Z4: 0.269 | AA4: 1.183 | AB4: 1.183 | AC4: -0.999 | AD4: -0.975 | AE4: -1.044 | AG4: 15.298 | AH4: inf | AJ4: 15.298 | AK4: -2.195 | AL4: 0.137 | AM4: -0.496 | AN4: 0.097 | AO4: 0.518 | AP4: -1 | AQ4: 0.293 | AR4: 0.106 | AS4: 0.058 | AT4: 0.001 | AU4: 0.047 | AV4: -0.055 | AW4: 0.219 | AX4: 0.14 | AY4: -0.505 | AZ4: -0.019 | BA4: -0.049 | BB4: 0.143 | BC4: 0.134 | BD4: 0.767 | BE4: -1.074
A5: 2023-10-31 | B5: 0.074 | C5: 0.077 | D5: -0.311 | E5: 0.236 | F5: 0.018 | G5: 0.093 | H5: -0.727 | I5: -1.206 | J5: -0.915 | K5: 0.094 | L5: 1.083 | M5: 2.147 | N5: 0.006 | O5: 0.007 | P5: 0.269 | Q5: -0.734 | R5: -0.658 | S5: 6.319 | T5: 0.134 | U5: -0.031 | V5: 19.649 | W5: -0.507 | X5: -2.643 | Y5: -1.577 | Z5: 0.117 | AA5: -0.394 | AB5: -0.394 | AC5: 1.442 | AD5: 86.185 | AE5: -12.227 | AG5: -0.956 | AJ5: -0.959 | AK5: -4.53 | AL5: -0.063 | AM5: inf | AN5: 0 | AO5: 0.042 | AP5: 0.061 | AQ5: -0.034 | AR5: 0.007 | AS5: 0.04 | AT5: 0.481 | AU5: 0.383 | AV5: 0 | AW5: 0.192 | AX5: 0.056 | AY5: 0.537 | AZ5: -0.106 | BA5: 0.008 | BB5: 0.033 | BC5: 0.102 | BD5: 1.248 | BE5: -1.205
A6: 2023-07-31 | B6: 0.056 | C6: 0.048 | D6: 0.855 | E6: -0.177 | F6: 0.058 | G6: 0.002 | H6: -8.539 | I6: -2.361 | J6: 0.009 | K6: 0.2 | L6: 0.046 | M6: 16.255 | N6: 0.006 | O6: 0.006 | P6: -0.171 | Q6: -1.475 | R6: -1.84 | S6: inf | T6: 0.108 | U6: 0.259 | V6: -0.62 | W6: -1.298 | X6: -1.472 | Y6: -0.094 | Z6: -0.186 | AA6: -0.235 | AB6: -0.235 | AC6: -9.966 | AD6: -0.792 | AE6: -0.368 | AG6: 16.694 | AJ6: 5.289 | AK6: -7.7 | AL6: 0.119 | AM6: -1 | AN6: 0.081 | AO6: 0.17 | AP6: 0.055 | AQ6: 0.118 | AR6: 0.092 | AS6: 0.058 | AT6: 0 | AU6: -0.049 | AV6: 0.029 | AW6: 0.029 | AX6: 0.074 | AY6: 1.194 | AZ6: -0.005 | BA6: -0.005 | BB6: 0.042 | BC6: 0.144 | BD6: -0.558 | BE6: 0.198
A7: 2023-04-30 | B7: 0.087 | C7: 0.133 | D7: -0.028 | E7: 0.141 | F7: 0.098 | G7: -0.067 | H7: -1.083 | I7: -1.184 | J7: 0.006 | K7: 0.13 | L7: -0.17 | M7: -1.01 | N7: 0.006 | O7: 0.024 | P7: 0.095 | Q7: -2.172 | R7: -0.54 | T7: 0.098 | U7: -0.141 | V7: -0.74 | W7: -0.085 | X7: -1.247 | Y7: -34.648 | Z7: 0.101 | AA7: 0.119 | AB7: 0.119 | AC7: 93.8 | AD7: -0.957 | AE7: -1.207 | AG7: -0.903 | AH7: -1 | AJ7: -0.71 | AK7: -1.034 | AL7: 0.152 | AM7: -0.6 | AN7: 0.083 | AO7: -0.264 | AP7: 0 | AQ7: 0.076 | AR7: 0.019 | AS7: 0.079 | AT7: 0 | AU7: -0.042 | AV7: 0.224 | AW7: 0.031 | AX7: 0.022 | AY7: -0.628 | AZ7: 0.243 | BA7: 0.01 | BB7: -0.01 | BC7: 0.099 | BD7: -2.245 | BE7: -0.684
A8: 2023-01-31 | B8: 0.097 | C8: 0.093 | D8: 0.01 | E8: 0.028 | F8: 0.023 | G8: 0.236 | H8: -4.709 | I8: 0.09 | J8: 0.003 | K8: 0.663 | L8: -0.401 | M8: -0.104 | N8: 0.005 | O8: 0.005 | P8: 0.194 | Q8: 1.118 | R8: -2.671 | T8: 0.179 | U8: 0.087 | V8: -2.437 | W8: 0.009 | X8: 1.084 | Y8: -1.075 | Z8: 0.125 | AA8: -0.049 | AB8: -0.049 | AC8: -1.006 | AD8: 23.935 | AE8: 2.276 | AF8: -1 | AG8: 17.438 | AH8: inf | AJ8: -239.886 | AK8: -3.033 | AL8: -0.005 | AM8: inf | AN8: 0.097 | AO8: 0.29 | AP8: 0.152 | AQ8: 0.362 | AR8: 0.136 | AS8: 0.168 | AT8: 0.001 | AU8: -0.029 | AV8: 0.019 | AW8: 0.095 | AX8: 0.125 | AY8: -0.492 | AZ8: 0.252 | BA8: 0.016 | BB8: 0.13 | BC8: 0.112 | BD8: 0.026 | BE8: -0.025
A9: 2022-10-31 | B9: 0.085 | C9: 0.071 | D9: 0.048 | E9: 0.066 | F9: 0.062 | G9: 0.126 | H9: -0.778 | I9: 0.168 | J9: 0 | K9: 1.102 | L9: 0.856 | M9: 0.108 | N9: 0.005 | O9: 0.005 | P9: 0.282 | Q9: 0.339 | R9: -0.35 | T9: 0.078 | U9: 0.065 | V9: -5.608 | W9: 0.357 | X9: 0.373 | Y9: -0.119 | Z9: 0.157 | AA9: -0.072 | AB9: -0.072 | AC9: -8.383 | AD9: 1.036 | AE9: 0.231 | AF9: -inf | AG9: -0.959 | AJ9: -1.003 | AK9: 0.477 | AL9: 0.064 | AN9: 0.064 | AO9: 0.159 | AP9: 162259999 | AQ9: -0.008 | AR9: 0.076 | AS9: 0.107 | AT9: 0.034 | AU9: -0.004 | AV9: 0.304 | AW9: 0.074 | AX9: 0.076 | AY9: 0.659 | AZ9: 0.01 | BA9: -0.004 | BB9: 0.076 | BC9: 0.076 | BD9: 0.243 | BE9: 0.01
A10: 2022-07-31 | B10: 0.097 | C10: 0.093 | D10: 0.181 | E10: 0.161 | F10: 0.167 | G10: 0.117 | H10: 0.052 | I10: 1.023 | J10: 0.101 | K10: 4.127 | L10: 0.389 | M10: 0.621 | N10: 0.033 | O10: 0.006 | P10: -0.134 | Q10: 45.947 | R10: -2.022 | T10: 0.072 | U10: 0.283 | V10: -1.084 | W10: -0.225 | X10: -0.216 | Y10: 0.074 | Z10: -0.023 | AA10: 0.276 | AB10: 0.276 | AC10: 0.711 | AD10: 0.77 | AE10: 0.299 | AG10: 10.674 | AJ10: 11.479 | AK10: -0.248 | AL10: 0.077 | AN10: 0.077 | AO10: 0.135 | AP10: -1 | AQ10: 0.195 | AR10: 0.089 | AS10: 0.193 | AT10: 0 | AU10: -0.044 | AV10: 0.241 | AW10: 0.068 | AX10: 0.083 | AY10: 3.882 | AZ10: 0.035 | BA10: -0.001 | BB10: 0.071 | BC10: 0.113 | BD10: 6.643 | BE10: 0.633
A11: 2022-04-30 | B11: 0.132 | C11: 0.134 | D11: -0.086 | E11: 0.19 | F11: 0.104 | G11: 0.175 | H11: 0.913 | I11: 0.015 | J11: -0.087 | K11: inf | L11: -0.747 | M11: -0.276 | N11: -0.02 | O11: 0.007 | P11: 0.232 | Q11: -0.988 | R11: -1.904 | S11: -1 | T11: -0.003 | U11: 0.106 | V11: -1.119 | W11: 0.252 | X11: -0.243 | Y11: 0.752 | Z11: 0.346 | AA11: 0.795 | AB11: 0.795 | AC11: -1.024 | AD11: 4.65 | AE11: -0.349 | AG11: -0.88 | AH11: -1 | AJ11: -0.881 | AK11: -0.205 | AL11: 0.078 | AN11: 0.078 | AO11: 0.003 | AP11: 0.07 | AQ11: -0.048 | AR11: 0.063 | AS11: 0.18 | AT11: -0.001 | AU11: -0.035 | AV11: 0.213 | AW11: 0.053 | AX11: 0.06 | AY11: -0.769 | AZ11: 0.015 | BA11: -0.004 | BB11: 0.054 | BC11: 0.076 | BD11: 0.135 | BE11: 0.738
A12: 2022-01-31 | B12: 0.134 | C12: 0.144 | D12: 0.326 | E12: -0.014 | F12: 0.072 | G12: 0.076 | H12: 1.433 | I12: -0.416 | J12: -0.016 | K12: -1 | L12: 2.036 | M12: -0.168 | N12: 0.006 | O12: 0.006 | P12: 0.037 | Q12: 4.169 | R12: -4.244 | S12: -inf | T12: 0.147 | U12: 0.069 | V12: 42.31 | W12: -0.1 | X12: 0.769 | Y12: -0.26 | Z12: 0.004 | AA12: -0.106 | AB12: -0.106 | AC12: -15.299 | AD12: -0.941 | AE12: 1.094 | AG12: 6.847 | AH12: inf | AJ12: 2.465 | AK12: 1.191 | AL12: 0.047 | AN12: 0.047 | AO12: 0.3 | AP12: 0.167 | AQ12: 0.308 | AR12: 0.089 | AS12: 0.059 | AT12: 0.114 | AU12: 0.175 | AV12: 0.043 | AW12: 0.115 | AX12: 0.097 | AY12: 5.646 | AZ12: 0.012 | BA12: -0.003 | BB12: 0.103 | BC12: 0.081 | BD12: -0.864 | BE12: -0.396
A13: 2021-10-31 | B13: 0.125 | C13: 0.126 | D13: 0.114 | E13: 0.072 | F13: 0.082 | G13: 0.079 | H13: 0.115 | I13: -0.151 | J13: 0.017 | K13: inf | L13: 0.055 | M13: -0.12 | N13: 0.009 | O13: 0.009 | P13: 0.668 | Q13: -0.706 | R13: -1.779 | T13: 0.11 | U13: 0.136 | V13: -2.111 | W13: 0.656 | X13: -0.104 | Y13: 0.18 | Z13: 0.466 | AA13: 0.04 | AB13: 0.04 | AC13: -13.537 | AD13: 0.417 | AE13: 0.086 | AG13: -0.9 | AJ13: -0.791 | AK13: -0.011 | AL13: 0.067 | AN13: 0.067 | AO13: 0.063 | AP13: 0.138 | AQ13: -0.411 | AR13: 0.048 | AS13: 0.101 | AT13: -0.001 | AU13: -0.032 | AV13: 0.6 | AW13: 0.063 | AX13: 0.052 | AY13: -0.635 | AZ13: 0.035 | BA13: -0.001 | BB13: 0.052 | BC13: 0.053 | BD13: -0.285 | BE13: -0.114
A14: 2021-07-31 | B14: 0.115 | C14: 0.102 | D14: 0.188 | E14: 0.139 | F14: 0.15 | G14: 0.157 | H14: -0.87 | I14: 0.512 | J14: 0.108 | L14: -0.915 | M14: -0.326 | N14: 0.01 | O14: 0.01 | P14: -0.372 | Q14: -2.771 | R14: -2.51 | S14: -1 | T14: 0.119 | U14: 0.403 | V14: -1.075 | W14: -0.681 | X14: 0.369 | Y14: -1.437 | Z14: -0.265 | AA14: 0.152 | AB14: 0.152 | AC14: -0.999 | AD14: 3.584 | AE14: -0.893 | AG14: 7.841 | AJ14: 12.871 | AK14: -2.204 | AL14: 0.061 | AN14: 0.061 | AO14: 0.262 | AP14: 0.118 | AQ14: 0.826 | AR14: 0.105 | AS14: 0.1 | AT14: -0.001 | AU14: -0.037 | AV14: 0.735 | AW14: 0.048 | AX14: 0.088 | AY14: 4.664 | AZ14: 0.004 | BA14: -0.002 | BB14: 0.097 | BC14: 0.068 | BD14: 0.845 | BE14: 0.401
A15: 2021-04-30 | B15: 0.143 | C15: 0.132 | D15: 0.194 | E15: 0.202 | F15: 0.2 | G15: 0.183 | H15: 5.991 | I15: 0.984 | J15: 4.418 | L15: 16.677 | M15: 3.476 | N15: 0.011 | O15: 0.011 | P15: 0.207 | Q15: -1.474 | R15: -3.215 | S15: 0.46 | T15: 0.214 | U15: 0.139 | V15: 49.16 | W15: 1.663 | X15: -0.121 | Y15: -1.272 | Z15: 0.289 | AA15: 0.752 | AB15: 0.752 | AC15: 7361.646 | AD15: -3.265 | AE15: 21.25 | AF15: -1 | AG15: -1.174 | AH15: -1 | AJ15: -0.997 | AK15: 0.204 | AL15: -0.122 | AN15: -0.122 | AO15: -0.117 | AP15: 0.056 | AQ15: 0.052 | AR15: -0.111 | AS15: 0.12 | AT15: 3.482 | AU15: 4.668 | AV15: 2.266 | AW15: 0.915 | AX15: 0.054 | AY15: -0.713 | AZ15: 0.04 | BA15: 0 | BB15: 0.09 | BC15: -0.021 | BD15: 3.279 | BE15: 1.225
A16: 2021-01-31 | B16: 0.14 | C16: 0.16 | D16: 0.11 | E16: 0.065 | F16: 0.075 | G16: 0.148 | H16: 1.507 | I16: -0.346 | J16: 4.435 | L16: 5.279 | M16: -0.225 | N16: 0.01 | O16: 0.01 | P16: 0.277 | Q16: 1.991 | R16: -2.549 | S16: -0.059 | T16: 0.129 | U16: 0.175 | V16: -0.547 | W16: 0.226 | X16: 1.36 | Y16: -179.594 | Z16: 0.293 | AA16: 0.391 | AB16: 0.391 | AC16: -0.999 | AD16: -2.156 | AE16: -0.824 | AF16: 0 | AG16: -2 | AH16: inf | AJ16: 146.076 | AK16: -10.438 | AL16: 0.81 | AM16: -1 | AN16: 0.81 | AO16: 0.384 | AP16: 0.295 | AQ16: 0.174 | AR16: 0.71 | AS16: 0.014 | AT16: 0.005 | AU16: -0.042 | AV16: 0 | AW16: 0.077 | AX16: 0.562 | AY16: 0.61 | AZ16: 0.038 | BA16: 21.644 | BB16: 0.991 | BC16: 0.07 | BD16: -0.71 | BE16: -0.187
A17: 2020-10-31 | B17: 0.168 | C17: 0.182 | D17: 0.103 | E17: 0.11 | F17: 0.109 | G17: 0.14 | H17: -0.628 | I17: -0.194 | J17: 0.109 | L17: 0.023 | M17: -0.179 | N17: 0.012 | O17: 0.012 | P17: 1.347 | Q17: 3.788 | R17: -1.628 | S17: -5.536 | T17: 0.1 | U17: 0.077 | V17: -0.572 | W17: 1.067 | X17: 0.281 | Y17: -1.08 | Z17: 0.608 | AA17: -0.451 | AB17: -0.451 | AC17: -inf | AD17: -0.5 | AE17: 3.167 | AF17: -inf | AG17: inf | AJ17: -0.812 | AK17: -1.134 | AL17: -0.005 | AM17: inf | AN17: -0.005 | AO17: 0.158 | AP17: 0.159 | AQ17: -0.052 | AR17: 0.019 | AS17: 0.036 | AT17: 9.224 | AU17: 46.135 | AV17: 0.25 | AW17: 0.358 | AX17: 0.082 | AY17: -0.259 | AZ17: 0 | BA17: -0.059 | BB17: 0.133 | BC17: 0.029 | BD17: -0.332 | BE17: -0.394
A18: 2020-07-31 | B18: 0.117 | C18: 0.102 | D18: 0.156 | E18: 0.079 | F18: 0.096 | G18: 0.244 | H18: -0.839 | I18: 0.328 | J18: 0.217 | L18: -0.574 | M18: 0.554 | N18: 0.017 | O18: 0.017 | P18: -0.627 | Q18: -1.224 | R18: 0.034 | S18: -3.422 | T18: 0.147 | U18: 0.595 | V18: -0.326 | W18: -0.709 | X18: -0.35 | Y18: -0.919 | Z18: -0.442 | AA18: 0.953 | AB18: 0.953 | AC18: -1 | AD18: -0.988 | AE18: -1.037 | AJ18: 2.996 | AK18: 64.333 | AL18: 0.059 | AN18: 0.059 | AO18: 0.035 | AP18: 0.008 | AQ18: 0.05 | AR18: 0.054 | AS18: 0.108 | AT18: 0.063 | AU18: -0.172 | AV18: 1 | AW18: 0.111 | AX18: 0.064 | AY18: 0.55 | AZ18: 0.295 | BA18: 0.098 | BB18: 0.077 | BC18: 0.052 | BD18: 0.434 | BE18: 0.667
A19: 2020-04-30 | B19: 0.171 | C19: 0.207 | D19: -0.011 | E19: 0.163 | F19: 0.119 | G19: 0.049 | H19: 0.415 | I19: -0.275 | J19: -0.014 | L19: 2.111 | M19: -0.323 | N19: 0.027 | O19: 0.027 | P19: 0.717 | Q19: -2.063 | R19: -1.504 | S19: -0.773 | T19: 0.169 | U19: -0.03 | V19: -3.967 | W19: 0.363 | X19: -0.407 | Y19: -2.546 | Z19: 0.491 | AA19: -0.25 | AB19: -0.25 | AC19: -0.096 | AD19: -0.857 | AE19: -2.109 | AG19: -1 | AH19: -1 | AJ19: -0.748 | AK19: -1.11 | AL19: 2.795 | AM19: -1 | AN19: 0.102 | AO19: -0.126 | AP19: 0.243 | AQ19: -0.111 | AR19: 0.066 | AS19: 0.285 | AT19: -0.009 | AU19: -0.205 | AV19: 0 | AW19: 0.161 | AX19: 0.081 | AY19: 3.854 | AZ19: -0.901 | BA19: inf | BB19: 0.157 | BC19: 0.014 | BD19: -0.406 | BE19: -0.345
A20: 2020-01-31 | B20: 0.216 | C20: 0.238 | D20: 0.172 | E20: 0.104 | F20: 0.12 | G20: 0.075 | H20: -0.105 | I20: -0.192 | J20: 0.098 | L20: -0.233 | M20: -0.2 | N20: 0.017 | O20: 0.017 | P20: 6.19 | Q20: -0.37 | R20: -inf | S20: inf | T20: 0.198 | U20: 0.109 | V20: 4.5 | W20: 0.399 | X20: 0.05 | Y20: -45.346 | Z20: 0.711 | AA20: -0.511 | AB20: -0.511 | AC20: 0.096 | AD20: 7.456 | AE20: 19.986 | AG20: inf | AH20: inf | AJ20: -29.213 | AK20: -1.278 | AL20: -0.644 | AM20: 6.185 | AN20: 0.094 | AO20: 0.132 | AP20: 0.196 | AQ20: 0.361 | AR20: 0.112 | AS20: 0.051 | AT20: -0.009 | AU20: -0.173 | AV20: inf | AW20: 0.15 | AX20: 0.119 | AY20: -0.744 | AZ20: 0.012 | BB20: 0.229 | BC20: 0.036 | BD20: -0.263 | BE20: -0.385
A21: 2019-10-31 | B21: 0.157 | C21: 0.147 | D21: -0.286 | E21: 0.052 | F21: -0.055 | G21: 0.138 | H21: -8.936 | I21: -0.239 | J21: -0.195 | L21: -0.317 | M21: -0.316 | N21: 0.569 | O21: 0.569 | P21: -1.242 | Q21: 0.094 | T21: 0.086 | U21: -0.264 | V21: -0.992 | W21: -14.999 | X21: 1.658 | Y21: -0.983 | Z21: -7.217 | AA21: 0.377 | AB21: 0.377 | AC21: 0.431 | AD21: 0.066 | AE21: -0.207 | AJ21: -1.001 | AK21: -2.49 | AL21: 0.015 | AM21: -0.042 | AN21: 0.008 | AO21: 0.264 | AP21: 0.056 | AQ21: 0.292 | AR21: 0.048 | AS21: 0.199 | AT21: 0.002 | AU21: -0.137 | AW21: 0.221 | AX21: 0.072 | AY21: 3.657 | AZ21: 0.261 | BB21: 0.215 | BC21: -0.015 | BD21: -0.279 | BE21: -0.058
A22: 2019-07-31 | B22: 0.125 | C22: 0.146 | D22: 1.551 | E22: 0.148 | F22: 0.391 | G22: 0.325 | H22: -2.145 | I22: 0.965 | J22: 163 | L22: 0.067 | M22: 0.997 | N22: -0.339 | O22: -0.339 | P22: 0.81 | Q22: -6.242 | R22: -1 | S22: -1 | T22: 0.088 | U22: 6.958 | V22: 10.71 | W22: -1.234 | X22: 0.58 | Y22: 138.545 | Z22: -5.392 | AA22: 0.309 | AB22: 0.309 | AC22: -0.332 | AD22: 0.27 | AE22: -9.311 | AJ22: -772.751 | AK22: 2.058 | AL22: 6.88 | AM22: 0.145 | AN22: 3.723 | AO22: 0.319 | AP22: 0.299 | AQ22: 0.296 | AR22: 2.23 | AS22: 0.251 | AT22: -0.004 | AU22: -0.16 | AW22: 0.137 | AX22: 1.562 | AY22: -0.886 | AZ22: 0.2 | BB22: -0.529 | BC22: -2.501 | BD22: 1.177 | BE22: 0.78
A23: 2019-04-30 | B23: 0.194 | C23: 0.25 | D23: -0.111 | E23: 0.152 | F23: 0.096 | G23: 0.085 | H23: 0.227 | I23: -0.175 | J23: inf | L23: 0.705 | M23: -0.169 | N23: 0.149 | O23: 0.149 | P23: 121.977 | Q23: -1.347 | R23: inf | S23: -inf | T23: 0.054 | U23: 0.21 | V23: 1.703 | W23: -0.621 | X23: -0.643 | Y23: -0.073 | Z23: -0.91 | AA23: 0.1 | AB23: 0.1 | AC23: 0.132 | AD23: -0.192 | AE23: -1.388 | AJ23: 1.714 | AK23: -1.642 | AL23: 0.052 | AM23: -0.205 | AN23: -0.087 | AO23: -0.055 | AP23: -0.432 | AQ23: 19.492 | AR23: -0.061 | AS23: 0.171 | AT23: -0.017 | AU23: -0.161 | AW23: 0.435 | AX23: 0.056 | AY23: 0.446 | AZ23: -0.154 | BB23: 1.629 | BC23: -7.499 | BD23: -0.216 | BE23: -0.097
A24: 2019-01-31 | B24: 0.212 | C24: 0.212 | D24: -0.019 | E24: 0.058 | F24: 0.041 | G24: -0.153 | H24: 0.059 | I24: -0.258 | L24: -0.348 | M24: -0.261 | N24: 0 | O24: 0 | P24: -0.99 | Q24: -0.228 | T24: 0.242 | U24: -0.77 | V24: -0.841 | W24: 1.269 | X24: 0.365 | Y24: -1.154 | Z24: -5.344 | AA24: 0.689 | AB24: 0.689 | AC24: -0.048 | AD24: 0.164 | AE24: -0.708 | AJ24: -1.04 | AK24: -4.268 | AL24: 0.059 | AM24: -0.044 | AN24: 0.001 | AO24: 0.2 | AP24: inf | AQ24: -0.97 | AR24: 0.084 | AS24: 0.523 | AT24: 0.008 | AU24: -0.917 | AW24: 0.212 | AX24: 0.112 | AY24: 0.196 | AZ24: inf | BB24: 0.603 | BC24: -0.227 | BD24: -0.308 | BE24: -0.111
A25: 2018-10-31 | B25: 0.404 | C25: 0.581 | D25: 1.009 | E25: 0.273 | F25: 0.388 | G25: 0.474 | H25: -2.595 | I25: 0.271 | J25: -1 | L25: 3.421 | M25: 0.259 | N25: 0 | O25: 0 | P25: -0.219 | Q25: -1.969 | T25: 0.218 | U25: 6.83 | V25: 10.91 | W25: -0.21 | X25: -9.197 | Y25: 1.328 | Z25: -0.431 | AA25: -0.089 | AB25: -0.089 | AC25: inf | AD25: -inf | AE25: 3.704 | AJ25: 17.027 | AK25: -0.446 | AL25: -2.269 | AM25: -0.179 | AN25: 1.91 | AO25: inf | AQ25: inf | AR25: 3.646 | AS25: inf | AT25: inf | AU25: inf | AW25: -2.277 | AX25: inf | AY25: inf | BB25: inf | BC25: -6.231 | BD25: 0.277 | BE25: 0.183
A26: 2018-04-30 | B26: 0.221 | C26: 0.427 | D26: 0.107 | E26: 0.069 | F26: 0.074 | G26: 0.106 | H26: -inf | I26: -0.099 | J26: inf | K26: -1 | L26: -0.749 | M26: -0.194 | N26: 2.976 | O26: 2.976 | P26: 0.647 | Q26: -2.06 | T26: -5.693 | U26: 0.285 | V26: inf | W26: -1.716 | X26: 0.09 | Y26: 3.69 | Z26: -0.049 | AA26: 2.006 | AB26: 2.006 | AE26: -147.34 | AJ26: -0.873 | AK26: -1.365 | AL26: -2.041 | AM26: 49.73 | AN26: 0 | AO26: -1 | AP26: -1 | AQ26: -1 | AR26: -0.572 | AS26: -1 | AT26: -1 | AU26: -1 | AW26: -2.026 | AX26: -1 | AY26: -1 | BA26: -1 | BB26: -1 | BC26: 0 | BD26: -0.2 | BE26: -0.014
A27: 2018-01-31

Sheet Yearly % Change
A1: date | B1: revenue | C1: grossProfit | D1: generalAndAdministrativeExpenses | E1: sellingAndMarketingExpenses | F1: sellingGeneralAndAdministrativeExpenses | G1: researchAndDevelopmentExpenses | H1: otherExpenses | I1: operatingIncome | J1: interestExpense | K1: interestIncome | L1: incomeTaxExpense | M1: netIncome | N1: weightedAverageShsOut | O1: weightedAverageShsOutDil | P1: freeCashFlow | Q1: accountsReceivables | R1: accountsPayables | S1: inventory_x | T1: depreciationAndAmortization | U1: stockBasedCompensation | V1: deferredIncomeTax | W1: changeInWorkingCapital | X1: otherWorkingCapital | Y1: netChangeInCash | Z1: netCashProvidedByOperatingActivities | AA1: capitalExpenditure | AB1: investmentsInPropertyPlantAndEquipment | AC1: acquisitionsNet | AD1: purchasesOfInvestments | AE1: netCashUsedForInvestingActivites | AF1: debtRepayment | AG1: commonStockIssued | AH1: commonStockRepurchased | AI1: dividendsPaid | AJ1: netCashUsedProvidedByFinancingActivities | AK1: effectOfForexChangesOnCash | AL1: cashAndCashEquivalents | AM1: shortTermInvestments | AN1: cashAndShortTermInvestments | AO1: netReceivables | AP1: inventory_y | AQ1: otherCurrentAssets | AR1: totalCurrentAssets | AS1: propertyPlantEquipmentNet | AT1: goodwill | AU1: intangibleAssets | AV1: longTermInvestments | AW1: totalNonCurrentAssets | AX1: totalAssets | AY1: accountPayables | AZ1: shortTermDebt | BA1: longTermDebt | BB1: totalLiabilities | BC1: totalEquity | BD1: EBITDA | BE1: FCFsimple
A2: 2024-07-31 | B2: 0.317 | C2: 0.322 | D2: -0.305 | E2: 0.536 | F2: 0.197 | G2: 0.399 | H2: -0.405 | I2: -1.921 | J2: 0.016 | K2: 0.406 | L2: 1.367 | M2: 4.549 | N2: 0.026 | O2: 0.038 | P2: 0.445 | Q2: -1.534 | R2: -1.022 | S2: -1 | T2: 0.552 | U2: 0.219 | V2: 16.258 | W2: 1.137 | X2: -3.944 | Y2: -0.01 | Z2: 0.334 | AA2: -0.04 | AB2: -0.04 | AC2: -1.051 | AD2: -0.536 | AE2: -2.195 | AG2: 0.231 | AJ2: 0.156 | AK2: -0.311 | AL2: 0.275 | AN2: 0.275 | AO2: 0.225 | AP2: -1 | AQ2: 0.575 | AR2: 0.217 | AS2: 0.142 | AT2: 0.676 | AU2: 0.462 | AV2: -0.022 | AW2: 0.546 | AX2: 0.305 | AY2: -0.432 | AZ2: 0.056 | BA2: -0.04 | BB2: 0.181 | BC2: 0.546 | BD2: 2.607 | BE2: -1.346
A3: 2024-04-30 | B3: 0.33 | C3: 0.33 | D3: 0.255 | E3: 0.245 | F3: 0.248 | G3: 0.314 | H3: 32.287 | I3: -0.386 | J3: 0.019 | K3: 0.502 | L3: 0.739 | M3: 86.21 | N3: 0.025 | O3: 0.04 | P3: 0.419 | Q3: -0.09 | R3: -1.015 | T3: 0.592 | U3: 0.399 | V3: 0 | W3: -0.605 | X3: 0.789 | Y3: -0.126 | Z3: 0.274 | AA3: -0.178 | AB3: -0.178 | AC3: -9.794 | AD3: -0.847 | AE3: -1.766 | AG3: -0.69 | AJ3: -1.382 | AK3: 9.089 | AL3: 0.308 | AM3: -1 | AN3: 0.264 | AO3: 0.524 | AP3: -1 | AQ3: 0.462 | AR3: 0.239 | AS3: 0.177 | AT3: 0.676 | AU3: 0.466 | AV3: 0.009 | AW3: 0.571 | AX3: 0.332 | AY3: 0.26 | AZ3: -0.012 | BA3: -0.045 | BB3: 0.22 | BC3: 0.572 | BD3: 0.328 | BE3: -0.855
A4: 2024-01-31 | B4: 0.326 | C4: 0.378 | D4: 0.209 | E4: 0.178 | F4: 0.18 | G4: 0.115 | H4: -2.3 | I4: -1.506 | J4: 0.011 | K4: 0.543 | L4: 1.561 | M4: -2.097 | N4: 0.025 | O4: 0.055 | P4: 0.313 | Q4: 1.013 | R4: -0.475 | S4: -inf | T4: 0.521 | U4: 0.157 | V4: 0.053 | W4: -0.919 | X4: 0.16 | Y4: -37.483 | Z4: 0.27 | AA4: 0.132 | AB4: 0.132 | AC4: -3.443 | AD4: -0.98 | AE4: -1.064 | AG4: 0.229 | AH4: 0.285 | AJ4: 0.229 | AK4: -0.038 | AL4: 0.375 | AM4: -0.602 | AN4: 0.284 | AO4: 0.362 | AP4: -1 | AQ4: 0.503 | AR4: 0.239 | AS4: 0.256 | AT4: 0.482 | AU4: 0.318 | AV4: 0.19 | AW4: 0.541 | AX4: 0.322 | AY4: -0.379 | AZ4: 0.085 | BA4: -0.036 | BB4: 0.218 | BC4: 0.571 | BD4: -3.183 | BE4: -0.994
A5: 2023-10-31 | B5: 0.353 | C5: 0.398 | D5: 0.255 | E5: 0.194 | F5: 0.21 | G5: 0.263 | H5: -1.632 | I5: -1.056 | J5: -0.914 | K5: 1.468 | L5: 0.083 | M5: -1.488 | N5: 0.024 | O5: 0.043 | P5: 0.376 | Q5: -0.686 | R5: -0.779 | S5: inf | T5: 0.627 | U5: 0.139 | V5: -3.937 | W5: -1.135 | X5: -1.4 | Y5: -2.326 | Z5: 0.126 | AA5: -0.507 | AB5: -0.507 | AC5: 11.931 | AD5: 18.268 | AE5: 3.813 | AF5: -1 | AG5: 0.39 | AJ5: -19.009 | AK5: 0.638 | AL5: 0.204 | AM5: inf | AN5: 0.284 | AO5: 0.158 | AP5: 0.289 | AQ5: 0.583 | AR5: 0.273 | AS5: 0.387 | AT5: 0.482 | AU5: 0.223 | AV5: 0.283 | AW5: 0.384 | AX5: 0.305 | AY5: -0.362 | AZ5: 0.384 | BA5: 0.029 | BB5: 0.204 | BC5: 0.541 | BD5: -2.268 | BE5: -1.075
A6: 2023-07-31 | B6: 0.367 | C6: 0.391 | D6: 0.909 | E6: 0.03 | F6: 0.261 | G6: 0.301 | H6: -1.513 | I6: -0.682 | J6: 0.017 | K6: 3.742 | L6: -0.035 | M6: -1.172 | N6: 0.023 | O6: 0.041 | P6: 0.391 | Q6: 0.578 | R6: -0.581 | S6: inf | T6: 0.546 | U6: 0.253 | V6: -0.345 | W6: -1.373 | X6: -0.666 | Y6: 1.025 | Z6: 0.166 | AA6: -0.245 | AB6: -0.245 | AC6: -40.084 | AD6: -0.55 | AE6: -1.528 | AG6: 0.294 | AJ6: 0.283 | AK6: -1.685 | AL6: 0.366 | AN6: 0.366 | AO6: 0.288 | AP6: 197110999 | AQ6: 0.625 | AR6: 0.361 | AS6: 0.477 | AT6: 0.035 | AU6: -0.119 | AV6: 0.673 | AW6: 0.248 | AX6: 0.329 | AY6: -0.311 | AZ6: 0.564 | BA6: 0.017 | BB6: 0.254 | BC6: 0.504 | BD6: -1.701 | BE6: -0.627
A7: 2023-04-30 | B7: 0.42 | C7: 0.45 | D7: 0.216 | E7: 0.453 | F7: 0.391 | G7: 0.451 | H7: -0.928 | I7: -1.473 | J7: 0.11 | K7: 19.253 | L7: 0.282 | M7: -1.016 | N7: 0.05 | O7: 0.041 | P7: 0.452 | Q7: -157.039 | R7: -0.49 | T7: 0.497 | U7: 0.277 | V7: -1.146 | W7: -0.029 | X7: -1.554 | Y7: 1.4 | Z7: 0.4 | AA7: 0.259 | AB7: 0.259 | AC7: 6.457 | AD7: 2.824 | AE7: -2.083 | AG7: -0.146 | AJ7: 1.546 | AK7: -0.923 | AL7: 0.314 | AM7: inf | AN7: 0.361 | AO7: 0.249 | AP7: 0.378 | AQ7: 0.736 | AR7: 0.357 | AS7: 0.664 | AT7: 0.035 | AU7: -0.114 | AV7: 1.019 | AW7: 0.296 | AX7: 0.339 | AY7: 0.533 | AZ7: 0.627 | BA7: 0.021 | BB7: 0.289 | BC7: 0.463 | BD7: -13.124 | BE7: -0.492
A8: 2023-01-31 | B8: 0.479 | C8: 0.45 | D8: 0.144 | E8: 0.516 | F8: 0.399 | G8: 0.827 | H8: -2.657 | I8: 1.613 | J8: 0.008 | K8: inf | L8: -0.609 | M8: 0.166 | N8: 0.023 | O8: 0.023 | P8: 0.633 | Q8: 0.663 | R8: -2.005 | S8: -1 | T8: 0.359 | U8: 0.645 | V8: -0.933 | W8: 0.329 | X8: 0.697 | Y8: -1.125 | Z8: 0.711 | AA8: 1.019 | AB8: 1.019 | AC8: -1.002 | AD8: 506.732 | AE8: 2.407 | AG8: 0.05 | AH8: 0.182 | AJ8: 0.04 | AK8: -2.793 | AL8: 0.23 | AM8: inf | AN8: 0.355 | AO8: 0.701 | AP8: 0.473 | AQ8: 0.536 | AR8: 0.416 | AS8: 0.821 | AT8: 0.034 | AU8: -0.107 | AV8: 1 | AW8: 0.324 | AX8: 0.389 | AY8: -0.047 | AZ8: 0.329 | BA8: 0.007 | BB8: 0.371 | BC8: 0.433 | BD8: 10.058 | BE8: 1.795
A9: 2022-10-31 | B9: 0.528 | C9: 0.518 | D9: 0.501 | E9: 0.453 | F9: 0.465 | G9: 0.59 | H9: 0.087 | I9: 0.401 | J9: -0.011 | K9: 14.942 | L9: 0.983 | M9: 0.083 | N9: 0.024 | O9: 0.024 | P9: 0.417 | Q9: 3.059 | R9: -2.95 | T9: 0.323 | U9: 0.617 | V9: -3.012 | W9: 0.185 | X9: 0.441 | Y9: 0.226 | Z9: 0.527 | AA9: 0.898 | AB9: 0.898 | AC9: -5.344 | AD9: 0.198 | AE9: 1.178 | AF9: -inf | AG9: -0.553 | AJ9: -1.015 | AK9: 0.932 | AL9: 0.293 | AN9: 0.293 | AO9: 0.713 | AP9: 0.494 | AQ9: 0.475 | AR9: 0.357 | AS9: 0.65 | AT9: 0.151 | AU9: 0.08 | AV9: 1.047 | AW9: 0.347 | AX9: 0.355 | AY9: 11.458 | AZ9: 0.074 | BA9: -0.011 | BB9: 0.338 | BC9: 0.394 | BD9: 0.464 | BE9: 0.732
A10: 2022-07-31 | B10: 0.585 | C10: 0.596 | D10: 0.594 | E10: 0.461 | F10: 0.494 | G10: 0.524 | H10: 4.46 | I10: 0.019 | J10: 0.006 | K10: inf | L10: 0.127 | M10: -0.14 | N10: 0.027 | O10: 0.027 | P10: 0.844 | Q10: -0.109 | R10: 1.335 | T10: 0.362 | U10: 0.724 | V10: -1.485 | W10: 0.446 | X10: -0.059 | Y10: 0.643 | Z10: 0.935 | AA10: 1.129 | AB10: 1.129 | AC10: -8.378 | AD10: -0.167 | AE10: 0.922 | AG10: 0.092 | AJ10: 0.071 | AK10: 0.294 | AL10: 0.298 | AN10: 0.298 | AO10: 0.571 | AP10: -1 | AQ10: -0.124 | AR10: 0.321 | AS10: 0.641 | AT10: 0.112 | AU10: 0.05 | AV10: 1.512 | AW10: 0.333 | AX10: 0.325 | AY10: 1.74 | AZ10: 0.1 | BA10: -0.009 | BB10: 0.308 | BC10: 0.364 | BD10: -0.157 | BE10: 0.52
A11: 2022-04-30 | B11: 0.611 | C11: 0.609 | D11: 0.604 | E11: 0.432 | F11: 0.473 | G11: 0.578 | H11: -0.326 | I11: -0.238 | J11: 0.012 | K11: inf | L11: -0.931 | M11: -0.642 | N11: 0.005 | O11: 0.031 | P11: 0.337 | Q11: -1.034 | R11: 2.449 | S11: -1 | T11: 0.421 | U11: 0.885 | V11: -1.431 | W11: -0.405 | X11: 0.643 | Y11: -1.668 | Z11: 0.457 | AA11: 0.923 | AB11: 0.923 | AC11: -1.004 | AD11: 1.158 | AE11: -0.842 | AG11: -0.173 | AJ11: 0.19 | AK11: -3.072 | AL11: 0.278 | AN11: 0.278 | AO11: 0.748 | AP11: 0.589 | AQ11: 0.339 | AR11: 0.341 | AS11: 0.513 | AT11: 0.111 | AU11: 0.057 | AV11: 2.511 | AW11: 0.308 | AX11: 0.331 | AY11: 2.179 | AZ11: 0.068 | BA11: -0.01 | BB11: 0.341 | BC11: 0.309 | BD11: -0.797 | BE11: 0.305
A12: 2022-01-31 | B12: 0.627 | C12: 0.606 | D12: 1.094 | E12: 0.446 | F12: 0.601 | G12: 0.589 | H12: 1.462 | I12: 0.489 | J12: 5.008 | L12: 3.796 | M12: 1.209 | N12: 0.036 | O12: 0.036 | P12: 0.31 | Q12: 0.277 | R12: 7.446 | S12: -2.574 | T12: 0.731 | U12: 0.942 | V12: 180.259 | W12: 0.265 | X12: 0.909 | Y12: -0.896 | Z12: 0.395 | AA12: 0.877 | AB12: 0.877 | AC12: 1265.083 | AD12: -1.865 | AE12: 4.414 | AF12: -1 | AG12: -2.205 | AH12: 0.467 | AJ12: -0.966 | AK12: -4.139 | AL12: 0.041 | AN12: 0.041 | AO12: 0.539 | AP12: 0.569 | AQ12: 0.48 | AR12: 0.122 | AS12: 0.436 | AT12: 3.983 | AU12: 5.209 | AV12: 8.453 | AW12: 1.379 | AX12: 0.324 | AY12: 2.948 | AZ12: 0.094 | BA12: -0.007 | BB12: 0.387 | BC12: 0.19 | BD12: -0.233 | BE12: 0.67
A13: 2021-10-31 | B13: 0.635 | C13: 0.629 | D13: 0.755 | E13: 0.562 | F13: 0.607 | G13: 0.697 | H13: 1.537 | I13: 0.667 | J13: 32.176 | K13: inf | L13: 8.918 | M13: 1.057 | N13: 0.041 | O13: 0.041 | P13: 0.614 | Q13: -0.261 | R13: 3.034 | S13: -1 | T13: 0.704 | U13: 1.134 | V13: 0.894 | W13: 0.724 | X13: 1.547 | Y13: -26.053 | Z13: 0.797 | AA13: 1.921 | AB13: 1.921 | AC13: -1.05 | AD13: 16 | AE13: -0.545 | AF13: -1 | AG13: -0.846 | AJ13: 0.461 | AK13: 12.524 | AL13: 0.8 | AM13: -1 | AN13: 0.8 | AO13: 0.64 | AP13: 0.74 | AQ13: 0.328 | AR13: 0.76 | AS13: 0.375 | AT13: 3.498 | AU13: 4.067 | AV13: 8.066 | AW13: 1.299 | AX13: 0.886 | AY13: -0.044 | AZ13: 0.123 | BA13: 21.556 | BB13: 1.503 | BC13: 0.178 | BD13: 0.638 | BE13: 1.248
A14: 2021-07-31 | B14: 0.697 | C14: 0.71 | D14: 0.738 | E14: 0.617 | F14: 0.646 | G14: 0.792 | H14: -0.154 | I14: 0.581 | J14: 35.184 | L14: 8.61 | M14: 0.919 | N14: 0.045 | O14: 0.045 | P14: 1.272 | Q14: 11.033 | R14: 2.255 | S14: -1 | T14: 0.689 | U14: 1.023 | V14: -1.73 | W14: 1.151 | X14: 2.64 | Y14: 0.708 | Z14: 0.971 | AA14: 0.541 | AB14: 0.541 | AC14: -inf | AD14: 5 | AE14: 0.744 | AG14: inf | AJ14: 0.314 | AK14: -2.832 | AL14: 0.678 | AN14: 0.678 | AO14: 0.786 | AP14: 0.773 | AQ14: 1.137 | AR14: 0.711 | AS14: 0.294 | AT14: 45.035 | AU14: 245.628 | AV14: 6.082 | AW14: 1.937 | AX14: 0.939 | AY14: 0.941 | AZ14: 0.085 | BA14: 20.258 | BB14: 1.697 | BC14: 0.151 | BD14: 0.53 | BE14: 0.536
A15: 2021-04-30 | B15: 0.701 | C15: 0.71 | D15: 0.692 | E15: 0.533 | F15: 0.568 | G15: 0.927 | H15: 0.052 | I15: 0.389 | J15: 38.741 | L15: 47.322 | M15: 3.425 | N15: 0.052 | O15: 0.052 | P15: 0.348 | Q15: 0.524 | R15: -3.23 | S15: 14.092 | T15: 0.731 | U15: 1.3 | V15: 5.553 | W15: 0.963 | X15: 0.728 | Y15: -1.316 | Z15: 0.497 | AA15: 1.611 | AB15: 1.611 | AC15: -188.783 | AD15: -0.985 | AE15: -1.606 | AG15: inf | AJ15: -0.622 | AK15: 98.417 | AL15: 0.677 | AN15: 0.677 | AO15: 0.465 | AP15: 0.599 | AQ15: 0.229 | AR15: 0.632 | AS15: 0.304 | AT15: 47.952 | AU15: 211.055 | AV15: 7.165 | AW15: 2.112 | AX15: 0.896 | AY15: -0.469 | AZ15: 0.399 | BA15: 22.395 | BB15: 1.646 | BC15: 0.133 | BD15: 0.189 | BE15: 0.826
A16: 2021-01-31 | B16: 0.742 | C16: 0.823 | D16: 0.401 | E16: 0.483 | F16: 0.463 | G16: 0.708 | H16: -0.787 | I16: -0.492 | J16: 6.234 | L16: 7.505 | M16: -0.331 | N16: 0.068 | O16: 0.068 | P16: 0.918 | Q16: 2.412 | R16: -1.508 | S16: 1.344 | T16: 0.666 | U16: 0.958 | V16: -1.388 | W16: 0.005 | X16: 0.165 | Y16: -2.793 | Z16: 0.731 | AA16: 0.118 | AB16: 0.118 | AC16: -1.023 | AD16: -1.001 | AE16: -0.97 | AF16: -inf | AG16: -1.032 | AH16: 1.771 | AJ16: 26.848 | AK16: -10.092 | AL16: 6.246 | AM16: -1 | AN16: 1.104 | AO16: 0.45 | AP16: 0.882 | AQ16: 0.039 | AR16: 0.956 | AS16: 0.495 | AT16: 9.822 | AU16: 28.748 | AV16: 1.5 | AW16: 0.887 | AX16: 0.945 | AY16: 7.97 | AZ16: -0.866 | BA16: inf | BB16: 1.809 | BC16: 0.174 | BD16: -0.835 | BE16: -0.462
A17: 2020-10-31 | B17: 0.858 | C17: 0.948 | D17: 0.478 | E17: 0.538 | F17: 0.523 | G17: 0.599 | H17: -0.924 | I17: -0.373 | J17: 0.462 | L17: 0.039 | M17: -0.309 | N17: 0.075 | O17: 0.075 | P17: 9.797 | Q17: -0.281 | R17: -inf | S17: inf | T17: 0.767 | U17: 0.849 | V17: -5.711 | W17: 0.146 | X17: -0.482 | Y17: -1.445 | Z17: 1.291 | AA17: -0.607 | AB17: -0.607 | AC17: -46.031 | AD17: -0.993 | AE17: 2.609 | AF17: -inf | AG17: inf | AJ17: -6.342 | AK17: -1.268 | AL17: 0.425 | AM17: -0.972 | AN17: 0.271 | AO17: 0.186 | AP17: 0.738 | AQ17: 0.205 | AR17: 0.273 | AS17: 0.55 | AT17: 9.666 | AU17: 24.677 | AV17: inf | AW17: 1.015 | AX17: 0.393 | AY17: 0.429 | AZ17: -0.87 | BA17: inf | BB17: 0.734 | BC17: 0.136 | BD17: -0.58 | BE17: -0.594
A18: 2020-07-31 | B18: 0.84 | C18: 0.889 | D18: -0.043 | E18: 0.457 | F18: 0.299 | G18: 0.596 | H18: -2.623 | I18: -0.408 | J18: 0.061 | L18: -0.306 | M18: -0.424 | N18: 0.666 | O18: 0.666 | P18: -2.112 | Q18: -0.836 | R18: inf | S18: -inf | T18: 0.744 | U18: 0.263 | V18: -1.089 | W18: -8.764 | X18: 0.075 | Y18: -0.907 | Z18: -9.855 | AA18: -0.015 | AB18: -0.015 | AC18: -1 | AD18: -0.985 | AE18: -0.314 | AJ18: -0.96 | AK18: -3.981 | AL18: 0.453 | AM18: -1 | AN18: 0.288 | AO18: 0.295 | AP18: 0.583 | AQ18: 0.641 | AR18: 0.309 | AS18: 0.794 | AT18: 0.045 | AU18: -0.53 | AV18: inf | AW18: 0.811 | AX18: 0.38 | AY18: 7.986 | AZ18: -0.836 | BA18: inf | BB18: 0.86 | BC18: 0.088 | BD18: -0.547 | BE18: -0.368
A19: 2020-04-30 | B19: 0.853 | C19: 0.964 | D19: 1.111 | E19: 0.551 | F19: 0.647 | G19: 0.7 | H19: 10.505 | I19: -0.124 | J19: 142 | L19: 0.741 | M19: -0.26 | N19: 0.084 | O19: 0.084 | P19: -6.4 | Q19: 2.842 | R19: 0.681 | S19: -1.227 | T19: 0.655 | U19: 5.3 | V19: -2.55 | W19: 5.247 | X19: 1.613 | Y19: 160.438 | Z19: 68.666 | AA19: -0.339 | AB19: -0.339 | AC19: -0.051 | AD19: 0.639 | AE19: 152.386 | AJ19: -8.815 | AK19: -1.14 | AL19: 9.807 | AM19: -1 | AN19: 4.741 | AO19: 0.651 | AP19: 1.039 | AQ19: 1.026 | AR19: 3.011 | AS19: 1.025 | AT19: -0.02 | AU19: -0.523 | AV19: inf | AW19: 0.854 | AX19: 2.322 | AY19: -0.342 | AZ19: -0.848 | BA19: inf | BB19: -0.187 | BC19: -2.552 | BD19: -0.312 | BE19: -0.325
A20: 2020-01-31 | B20: 0.891 | C20: 1.033 | D20: 0.898 | E20: 0.536 | F20: 0.613 | G20: 0.758 | H20: 8.978 | I20: -0.003 | J20: inf | L20: -0.046 | M20: -0.091 | N20: 0.212 | O20: 0.212 | P20: -387.84 | Q20: 0.256 | R20: -inf | S20: inf | T20: 0.491 | U20: 6.854 | V20: 0.412 | W20: 0.737 | X20: 0.573 | Y20: -97.807 | Z20: 3.182 | AA20: -0.032 | AB20: -0.032 | AC20: 0.188 | AD20: 8.254 | AE20: 52.614 | AG20: inf | AH20: inf | AJ20: -85.031 | AK20: -1.813 | AL20: 1.995 | AM20: 5.269 | AN20: 3.759 | AO20: 0.784 | AP20: -0.069 | AQ20: 45.71 | AR20: 2.536 | AS20: 0.846 | AT20: -0.028 | AU20: -0.497 | AV20: inf | AW20: 1.291 | AX20: 2.243 | AY20: -0.804 | AZ20: 0.296 | BB20: 0.847 | BC20: 8.947 | BD20: -0.092 | BE20: -0.07
A21: 2019-10-31 | B21: 0.885 | C21: 0.99 | D21: 0.588 | E21: 0.473 | F21: 0.499 | G21: 0.386 | H21: 10.812 | I21: -0.085 | J21: inf | L21: -0.189 | M21: -0.161 | N21: 0.192 | O21: 0.192 | P21: -1.539 | Q21: 0.537 | T21: 0.545 | U21: 0.632 | V21: -0.959 | W21: 1.819 | X21: 1.045 | Y21: -1.337 | Z21: -11.617 | AA21: 2.347 | AB21: 2.347 | AC21: 0.031 | AD21: 0.274 | AE21: -0.253 | AJ21: -1.12 | AK21: -10.561 | AL21: 7.91 | AM21: -0.166 | AN21: 3.355 | AO21: 0.891 | AP21: inf | AQ21: 0.023 | AR21: 2.447 | AS21: 1.675 | AT21: -0.011 | AU21: -0.949 | AW21: 1.415 | AX21: 2.224 | AY21: -0.085 | AZ21: inf | BB21: 1.41 | BC21: 6.426 | BD21: -0.148 | BE21: 0.346
A22: 2019-07-31 | B22: 1.286 | C22: 1.743 | D22: 3.465 | E22: 0.783 | F22: 1.202 | G22: 0.796 | H22: 1.374 | I22: 0.529 | J22: -0.146 | L22: 4.248 | M22: 0.544 | N22: -0.24 | O22: -0.24 | P22: 0.741 | Q22: -2.362 | T22: 0.734 | U22: 16.37 | V22: 59.051 | W22: -1.159 | X22: -7.306 | Y22: -47.451 | Z22: -0.028 | AA22: 1.216 | AB22: 1.216 | AC22: inf | AD22: -inf | AE22: 3.434 | AJ22: 1515 | AK22: 2.554 | AL22: -12.142 | AM22: -0.285 | AN22: 11.571 | AO22: inf | AP22: inf | AQ22: inf | AR22: 14.287 | AS22: inf | AT22: inf | AU22: inf | AW22: -3.526 | AX22: inf | AY22: inf | AZ22: inf | BB22: inf | BC22: -40.446 | BD22: 0.508 | BE22: 0.69
A23: 2019-04-30 | B23: 1.482 | C23: 2.418 | D23: 0.938 | E23: 0.659 | F23: 0.701 | G23: 0.499 | H23: inf | I23: -0.299 | J23: inf | K23: -1 | L23: 0.232 | M23: -0.377 | N23: 3.568 | O23: 3.568 | P23: 0.584 | Q23: -1.275 | R23: inf | S23: -inf | T23: -8.48 | U23: 1.804 | V23: inf | W23: -1.486 | X23: -5.352 | Y23: -2.561 | Z23: -1.21 | AA23: 4.087 | AB23: 4.087 | AC23: inf | AD23: -inf | AE23: 77.075 | AJ23: -1.25 | AK23: -1.424 | AL23: 0.472 | AM23: 30.649 | AN23: 1.662 | AO23: 0.465 | AP23: 26192999 | AQ23: -0.198 | AR23: 1.026 | AS23: 1.799 | AT23: -0.073 | AU23: -0.924 | AW23: 1.28 | AX23: 1.101 | AY23: -0.191 | AZ23: inf | BA23: -1 | BB23: 2.991 | BC23: 25.285 | BD23: -0.446 | BE23: -0.064
A24: 2019-01-31
A25: 2018-10-31
A26: 2018-04-30
A27: 2018-01-31

Sheet Annual Aggregated
